Workbook

Sheet HUONG DAN
A1: CHƯƠNG TRÌNH DỰ ĐOÁN BÓNG ĐÁ WORLD CUP 2026
A3: Sân chơi giao lưu — 100 người chơi — Vui cùng trái bóng tròn
A5: I. GIỚI THIỆU
A6: • Chương trình dự đoán 104 trận đấu World Cup 2026 cho 100 người chơi. • Thời gian thi đấu hiển thị theo GIỜ VIỆT NAM (GMT+7). • Thứ tự trận đấu theo đúng FIFA Match ID (Trận 1 - 104). • Trên Google Sheets, hệ thống tự động: phân quyền theo email, khóa sau giờ trận, gửi email nhắc nhở, đồng bộ tỉ số từ API, dashboard biểu đồ.
A12: II. LUẬT CHƠI & CÁCH TÍNH ĐIỂM
A14: 1. Điểm cơ sở mỗi trận:
B15: Loại dự đoán | C15: Mô tả | D15: Điểm
B16: Đúng tỉ số chính xác | C16: Đoán đúng cả 2 số bàn thắng (VD: 2-1 → 2-1) | D16: 3
B17: Đúng hiệu số | C17: Sai tỉ số nhưng đúng hiệu số bàn (VD: 2-1 → 3-2) | D17: 2
B18: Đúng kết quả | C18: Chỉ đúng đội thắng/hòa/thua | D18: 1
B19: Sai | C19: Không đoán đúng kết quả | D19: 0
A21: 2. Hệ số nhân theo vòng đấu:
B22: Vòng đấu | C22: Số trận | D22: Hệ số
B23: Vòng bảng | C23: 72 | D23: 1
B24: Vòng 1/16 (R32) | C24: 16 | D24: 1.5
B25: Vòng 1/8 (R16) | C25: 8 | D25: 2
B26: Tứ kết | C26: 4 | D26: 2.5
B27: Bán kết | C27: 2 | D27: 3
B28: Tranh hạng 3 | C28: 1 | D28: 2
B29: Chung kết | C29: 1 | D29: 4

Sheet BẢNG ĐẤU
A1: ⚽ BẢNG XẾP HẠNG 12 BẢNG ĐẤU — WORLD CUP 2026
A2: Tự động cập nhật theo kết quả nhập ở sheet DU DOAN (cột K, L) và thẻ phạt ở sheet THE PHAT. Xếp hạng theo: Điểm → Hiệu số → Bàn thắng (quy định FIFA WC 2026).
A3: 🟢 Nhất bảng - vào R32 | L3: 🟢 Nhì bảng - vào R32 | W3: 🟡 Hạng 3 - đợi xét (8 best 3rd vào R32)
A5: BẢNG A | O5: BẢNG B | AC5: BẢNG C
A6: # | B6: 🏴 | C6: Đội tuyển | D6: Đá | E6: T | F6: H | G6: B | H6: GF | I6: GA | J6: GD | K6: 🟨 | L6: 🟥 | M6: Pts | O6: # | P6: 🏴 | Q6: Đội tuyển | R6: Đá | S6: T | T6: H | U6: B | V6: GF | W6: GA | X6: GD | Y6: 🟨 | Z6: 🟥 | AA6: Pts | AC6: # | AD6: 🏴 | AE6: Đội tuyển | AF6: Đá | AG6: T | AH6: H | AI6: B | AJ6: GF | AK6: GA | AL6: GD | AM6: 🟨 | AN6: 🟥 | AO6: Pts | AY6: A | AZ6: Mexico | BA6: 🇲🇽 | BB6: =SUMPRODUCT(('DU DOAN'!$B$4:$B$107="Vòng bảng")*('DU DOAN'!$D$4:$D$107="A")*ISNUMBER('DU DOAN'!$K$4:$K$107)*ISNUMBER('DU DOAN'!$L$4:$L$107)*(('DU DOAN'!$H$4:$H$107="Mexico")+('DU DOAN'!$I$4:$I$107="Mexico"))) -> 0 | BC6: =SUMPRODUCT(('DU DOAN'!$B$4:$B$107="Vòng bảng")*('DU DOAN'!$D$4:$D$107="A")*ISNUMBER('DU DOAN'!$K$4:$K$107)*ISNUMBER('DU DOAN'!$L$4:$L$107)*(('DU DOAN'!$H$4:$H$107="Mexico")*('DU DOAN'!$K$4:$K$107>'DU DOAN'!$L$4:$L$107)+('DU DOAN'!$I$4:$I$107="Mexico")*('DU DOAN'!$L$4:$L$107>'DU DOAN'!$K$4:$K$107))) -> 0 | BD6: =SUMPRODUCT(('DU DOAN'!$B$4:$B$107="Vòng bảng")*('DU DOAN'!$D$4:$D$107="A")*ISNUMBER('DU DOAN'!$K$4:$K$107)*ISNUMBER('DU DOAN'!$L$4:$L$107)*(('DU DOAN'!$H$4:$H$107="Mexico")*('DU DOAN'!$K$4:$K$107='DU DOAN'!$L$4:$L$107)+('DU DOAN'!$I$4:$I$107="Mexico")*('DU DOAN'!$K$4:$K$107='DU DOAN'!$L$4:$L$107))) -> 0 | BE6: =SUMPRODUCT(('DU DOAN'!$B$4:$B$107="Vòng bảng")*('DU DOAN'!$D$4:$D$107="A")*ISNUMBER('DU DOAN'!$K$4:$K$107)*ISNUMBER('DU DOAN'!$L$4:$L$107)*(('DU DOAN'!$H$4:$H$107="Mexico")*('DU DOAN'!$K$4:$K$107<'DU DOAN'!$L$4:$L$107)+('DU DOAN'!$I$4:$I$107="Mexico")*('DU DOAN'!$L$4:$L$107<'DU DOAN'!$K$4:$K$107))) -> 0 | BF6: =SUMPRODUCT(('DU DOAN'!$B$4:$B$107="Vòng bảng")*('DU DOAN'!$D$4:$D$107="A")*ISNUMBER('DU DOAN'!$K$4:$K$107)*ISNUMBER('DU DOAN'!$L$4:$L$107)*(('DU DOAN'!$H$4:$H$107="Mexico")*'DU DOAN'!$K$4:$K$107+('DU DOAN'!$I$4:$I$107="Mexico")*'DU DOAN'!$L$4:$L$107)) -> 0 | BG6: =SUMPRODUCT(('DU DOAN'!$B$4:$B$107="Vòng bảng")*('DU DOAN'!$D$4:$D$107="A")*ISNUMBER('DU DOAN'!$K$4:$K$107)*ISNUMBER('DU DOAN'!$L$4:$L$107)*(('DU DOAN'!$H$4:$H$107="Mexico")*'DU DOAN'!$L$4:$L$107+('DU DOAN'!$I$4:$I$107="Mexico")*'DU DOAN'!$K$4:$K$107)) -> 0 | BH6: =BF6-BG6 -> 0 | BI6: =SUMPRODUCT(IFERROR((#REF!="Mexico")*#REF!,0))+SUMPRODUCT(IFERROR((#REF!="Mexico")*#REF!,0)) -> 0 | BJ6: =SUMPRODUCT(IFERROR((#REF!="Mexico")*#REF!,0))+SUMPRODUCT(IFERROR((#REF!="Mexico")*#REF!,0)) -> 0 | BK6: =3*BC6+BD6 -> 0 | BL6: =BK6*1000000+BH6*10000+BF6*100+4 -> 4
A7: 1 | B7: {=INDEX($BA$6:$BA$9,MATCH(LARGE($BL$6:$BL$9,1),$BL$6:$BL$9,0))} -> 🇲🇽 | C7: {=INDEX($AZ$6:$AZ$9,MATCH(LARGE($BL$6:$BL$9,1),$BL$6:$BL$9,0))} -> Mexico | D7: {=INDEX($AZ$6:$BL$9,MATCH(LARGE($BL$6:$BL$9,1),$BL$6:$BL$9,0),3)} -> 0 | E7: {=INDEX($AZ$6:$BL$9,MATCH(LARGE($BL$6:$BL$9,1),$BL$6:$BL$9,0),4)} -> 0 | F7: {=INDEX($AZ$6:$BL$9,MATCH(LARGE($BL$6:$BL$9,1),$BL$6:$BL$9,0),5)} -> 0 | G7: {=INDEX($AZ$6:$BL$9,MATCH(LARGE($BL$6:$BL$9,1),$BL$6:$BL$9,0),6)} -> 0 | H7: {=INDEX($AZ$6:$BL$9,MATCH(LARGE($BL$6:$BL$9,1),$BL$6:$BL$9,0),7)} -> 0 | I7: {=INDEX($AZ$6:$BL$9,MATCH(LARGE($BL$6:$BL$9,1),$BL$6:$BL$9,0),8)} -> 0 | J7: {=INDEX($AZ$6:$BL$9,MATCH(LARGE($BL$6:$BL$9,1),$BL$6:$BL$9,0),9)} -> 0 | K7: {=INDEX($AZ$6:$BL$9,MATCH(LARGE($BL$6:$BL$9,1),$BL$6:$BL$9,0),10)} -> 0 | L7: {=INDEX($AZ$6:$BL$9,MATCH(LARGE($BL$6:$BL$9,1),$BL$6:$BL$9,0),11)} -> 0 | M7: {=INDEX($AZ$6:$BL$9,MATCH(LARGE($BL$6:$BL$9,1),$BL$6:$BL$9,0),12)} -> 0 | O7: 1 | P7: {=INDEX($BA$11:$BA$14,MATCH(LARGE($BL$11:$BL$14,1),$BL$11:$BL$14,0))} -> 🇨🇦 | Q7: {=INDEX($AZ$11:$AZ$14,MATCH(LARGE($BL$11:$BL$14,1),$BL$11:$BL$14,0))} -> Canada | R7: {=INDEX($AZ$11:$BL$14,MATCH(LARGE($BL$11:$BL$14,1),$BL$11:$BL$14,0),3)} -> 0 | S7: {=INDEX($AZ$11:$BL$14,MATCH(LARGE($BL$11:$BL$14,1),$BL$11:$BL$14,0),4)} -> 0 | T7: {=INDEX($AZ$11:$BL$14,MATCH(LARGE($BL$11:$BL$14,1),$BL$11:$BL$14,0),5)} -> 0 | U7: {=INDEX($AZ$11:$BL$14,MATCH(LARGE($BL$11:$BL$14,1),$BL$11:$BL$14,0),6)} -> 0 | V7: {=INDEX($AZ$11:$BL$14,MATCH(LARGE($BL$11:$BL$14,1),$BL$11:$BL$14,0),7)} -> 0 | W7: {=INDEX($AZ$11:$BL$14,MATCH(LARGE($BL$11:$BL$14,1),$BL$11:$BL$14,0),8)} -> 0 | X7: {=INDEX($AZ$11:$BL$14,MATCH(LARGE($BL$11:$BL$14,1),$BL$11:$BL$14,0),9)} -> 0 | Y7: {=INDEX($AZ$11:$BL$14,MATCH(LARGE($BL$11:$BL$14,1),$BL$11:$BL$14,0),10)} -> 0 | Z7: {=INDEX($AZ$11:$BL$14,MATCH(LARGE($BL$11:$BL$14,1),$BL$11:$BL$14,0),11)} -> 0 | AA7: {=INDEX($AZ$11:$BL$14,MATCH(LARGE($BL$11:$BL$14,1),$BL$11:$BL$14,0),12)} -> 0 | AC7: 1 | AD7: {=INDEX($BA$16:$BA$19,MATCH(LARGE($BL$16:$BL$19,1),$BL$16:$BL$19,0))} -> 🇧🇷 | AE7: {=INDEX($AZ$16:$AZ$19,MATCH(LARGE($BL$16:$BL$19,1),$BL$16:$BL$19,0))} -> Brazil | AF7: {=INDEX($AZ$16:$BL$19,MATCH(LARGE($BL$16:$BL$19,1),$BL$16:$BL$19,0),3)} -> 0 | AG7: {=INDEX($AZ$16:$BL$19,MATCH(LARGE($BL$16:$BL$19,1),$BL$16:$BL$19,0),4)} -> 0 | AH7: {=INDEX($AZ$16:$BL$19,MATCH(LARGE($BL$16:$BL$19,1),$BL$16:$BL$19,0),5)} -> 0 | AI7: {=INDEX($AZ$16:$BL$19,MATCH(LARGE($BL$16:$BL$19,1),$BL$16:$BL$19,0),6)} -> 0 | AJ7: {=INDEX($AZ$16:$BL$19,MATCH(LARGE($BL$16:$BL$19,1),$BL$16:$BL$19,0),7)} -> 0 | AK7: {=INDEX($AZ$16:$BL$19,MATCH(LARGE($BL$16:$BL$19,1),$BL$16:$BL$19,0),8)} -> 0 | AL7: {=INDEX($AZ$16:$BL$19,MATCH(LARGE($BL$16:$BL$19,1),$BL$16:$BL$19,0),9)} -> 0 | AM7: {=INDEX($AZ$16:$BL$19,MATCH(LARGE($BL$16:$BL$19,1),$BL$16:$BL$19,0),10)} -> 0 | AN7: {=INDEX($AZ$16:$BL$19,MATCH(LARGE($BL$16:$BL$19,1),$BL$16:$BL$19,0),11)} -> 0 | AO7: {=INDEX($AZ$16:$BL$19,MATCH(LARGE($BL$16:$BL$19,1),$BL$16:$BL$19,0),12)} -> 0 | AZ7: Korea Republic | BA7: 🇰🇷 | BB7: =SUMPRODUCT(('DU DOAN'!$B$4:$B$107="Vòng bảng")*('DU DOAN'!$D$4:$D$107="A")*ISNUMBER('DU DOAN'!$K$4:$K$107)*ISNUMBER('DU DOAN'!$L$4:$L$107)*(('DU DOAN'!$H$4:$H$107="Korea Republic")+('DU DOAN'!$I$4:$I$107="Korea Republic"))) -> 0 | BC7: =SUMPRODUCT(('DU DOAN'!$B$4:$B$107="Vòng bảng")*('DU DOAN'!$D$4:$D$107="A")*ISNUMBER('DU DOAN'!$K$4:$K$107)*ISNUMBER('DU DOAN'!$L$4:$L$107)*(('DU DOAN'!$H$4:$H$107="Korea Republic")*('DU DOAN'!$K$4:$K$107>'DU DOAN'!$L$4:$L$107)+('DU DOAN'!$I$4:$I$107="Korea Republic")*('DU DOAN'!$L$4:$L$107>'DU DOAN'!$K$4:$K$107))) -> 0 | BD7: =SUMPRODUCT(('DU DOAN'!$B$4:$B$107="Vòng bảng")*('DU DOAN'!$D$4:$D$107="A")*ISNUMBER('DU DOAN'!$K$4:$K$107)*ISNUMBER('DU DOAN'!$L$4:$L$107)*(('DU DOAN'!$H$4:$H$107="Korea Republic")*('DU DOAN'!$K$4:$K$107='DU DOAN'!$L$4:$L$107)+('DU DOAN'!$I$4:$I$107="Korea Republic")*('DU DOAN'!$K$4:$K$107='DU DOAN'!$L$4:$L$107))) -> 0 | BE7: =SUMPRODUCT(('DU DOAN'!$B$4:$B$107="Vòng bảng")*('DU DOAN'!$D$4:$D$107="A")*ISNUMBER('DU DOAN'!$K$4:$K$107)*ISNUMBER('DU DOAN'!$L$4:$L$107)*(('DU DOAN'!$H$4:$H$107="Korea Republic")*('DU DOAN'!$K$4:$K$107<'DU DOAN'!$L$4:$L$107)+('DU DOAN'!$I$4:$I$107="Korea Republic")*('DU DOAN'!$L$4:$L$107<'DU DOAN'!$K$4:$K$107))) -> 0 | BF7: =SUMPRODUCT(('DU DOAN'!$B$4:$B$107="Vòng bảng")*('DU DOAN'!$D$4:$D$107="A")*ISNUMBER('DU DOAN'!$K$4:$K$107)*ISNUMBER('DU DOAN'!$L$4:$L$107)*(('DU DOAN'!$H$4:$H$107="Korea Republic")*'DU DOAN'!$K$4:$K$107+('DU DOAN'!$I$4:$I$107="Korea Republic")*'DU DOAN'!$L$4:$L$107)) -> 0 | BG7: =SUMPRODUCT(('DU DOAN'!$B$4:$B$107="Vòng bảng")*('DU DOAN'!$D$4:$D$107="A")*ISNUMBER('DU DOAN'!$K$4:$K$107)*ISNUMBER('DU DOAN'!$L$4:$L$107)*(('DU DOAN'!$H$4:$H$107="Korea Republic")*'DU DOAN'!$L$4:$L$107+('DU DOAN'!$I$4:$I$107="Korea Republic")*'DU DOAN'!$K$4:$K$107)) -> 0 | BH7: =BF7-BG7 -> 0 | BI7: =SUMPRODUCT(IFERROR((#REF!="Korea Republic")*#REF!,0))+SUMPRODUCT(IFERROR((#REF!="Korea Republic")*#REF!,0)) -> 0 | BJ7: =SUMPRODUCT(IFERROR((#REF!="Korea Republic")*#REF!,0))+SUMPRODUCT(IFERROR((#REF!="Korea Republic")*#REF!,0)) -> 0 | BK7: =3*BC7+BD7 -> 0 | BL7: =BK7*1000000+BH7*10000+BF7*100+3 -> 3
A8: 2 | B8: {=INDEX($BA$6:$BA$9,MATCH(LARGE($BL$6:$BL$9,2),$BL$6:$BL$9,0))} -> 🇰🇷 | C8: {=INDEX($AZ$6:$AZ$9,MATCH(LARGE($BL$6:$BL$9,2),$BL$6:$BL$9,0))} -> Korea Republic | D8: {=INDEX($AZ$6:$BL$9,MATCH(LARGE($BL$6:$BL$9,2),$BL$6:$BL$9,0),3)} -> 0 | E8: {=INDEX($AZ$6:$BL$9,MATCH(LARGE($BL$6:$BL$9,2),$BL$6:$BL$9,0),4)} -> 0 | F8: {=INDEX($AZ$6:$BL$9,MATCH(LARGE($BL$6:$BL$9,2),$BL$6:$BL$9,0),5)} -> 0 | G8: {=INDEX($AZ$6:$BL$9,MATCH(LARGE($BL$6:$BL$9,2),$BL$6:$BL$9,0),6)} -> 0 | H8: {=INDEX($AZ$6:$BL$9,MATCH(LARGE($BL$6:$BL$9,2),$BL$6:$BL$9,0),7)} -> 0 | I8: {=INDEX($AZ$6:$BL$9,MATCH(LARGE($BL$6:$BL$9,2),$BL$6:$BL$9,0),8)} -> 0 | J8: {=INDEX($AZ$6:$BL$9,MATCH(LARGE($BL$6:$BL$9,2),$BL$6:$BL$9,0),9)} -> 0 | K8: {=INDEX($AZ$6:$BL$9,MATCH(LARGE($BL$6:$BL$9,2),$BL$6:$BL$9,0),10)} -> 0 | L8: {=INDEX($AZ$6:$BL$9,MATCH(LARGE($BL$6:$BL$9,2),$BL$6:$BL$9,0),11)} -> 0 | M8: {=INDEX($AZ$6:$BL$9,MATCH(LARGE($BL$6:$BL$9,2),$BL$6:$BL$9,0),12)} -> 0 | O8: 2 | P8: {=INDEX($BA$11:$BA$14,MATCH(LARGE($BL$11:$BL$14,2),$BL$11:$BL$14,0))} -> 🇨🇭 | Q8: {=INDEX($AZ$11:$AZ$14,MATCH(LARGE($BL$11:$BL$14,2),$BL$11:$BL$14,0))} -> Switzerland | R8: {=INDEX($AZ$11:$BL$14,MATCH(LARGE($BL$11:$BL$14,2),$BL$11:$BL$14,0),3)} -> 0 | S8: {=INDEX($AZ$11:$BL$14,MATCH(LARGE($BL$11:$BL$14,2),$BL$11:$BL$14,0),4)} -> 0 | T8: {=INDEX($AZ$11:$BL$14,MATCH(LARGE($BL$11:$BL$14,2),$BL$11:$BL$14,0),5)} -> 0 | U8: {=INDEX($AZ$11:$BL$14,MATCH(LARGE($BL$11:$BL$14,2),$BL$11:$BL$14,0),6)} -> 0 | V8: {=INDEX($AZ$11:$BL$14,MATCH(LARGE($BL$11:$BL$14,2),$BL$11:$BL$14,0),7)} -> 0 | W8: {=INDEX($AZ$11:$BL$14,MATCH(LARGE($BL$11:$BL$14,2),$BL$11:$BL$14,0),8)} -> 0 | X8: {=INDEX($AZ$11:$BL$14,MATCH(LARGE($BL$11:$BL$14,2),$BL$11:$BL$14,0),9)} -> 0 | Y8: {=INDEX($AZ$11:$BL$14,MATCH(LARGE($BL$11:$BL$14,2),$BL$11:$BL$14,0),10)} -> 0 | Z8: {=INDEX($AZ$11:$BL$14,MATCH(LARGE($BL$11:$BL$14,2),$BL$11:$BL$14,0),11)} -> 0 | AA8: {=INDEX($AZ$11:$BL$14,MATCH(LARGE($BL$11:$BL$14,2),$BL$11:$BL$14,0),12)} -> 0 | AC8: 2 | AD8: {=INDEX($BA$16:$BA$19,MATCH(LARGE($BL$16:$BL$19,2),$BL$16:$BL$19,0))} -> 🏴󠁧󠁢󠁳󠁣󠁴󠁿 | AE8: {=INDEX($AZ$16:$AZ$19,MATCH(LARGE($BL$16:$BL$19,2),$BL$16:$BL$19,0))} -> Scotland | AF8: {=INDEX($AZ$16:$BL$19,MATCH(LARGE($BL$16:$BL$19,2),$BL$16:$BL$19,0),3)} -> 0 | AG8: {=INDEX($AZ$16:$BL$19,MATCH(LARGE($BL$16:$BL$19,2),$BL$16:$BL$19,0),4)} -> 0 | AH8: {=INDEX($AZ$16:$BL$19,MATCH(LARGE($BL$16:$BL$19,2),$BL$16:$BL$19,0),5)} -> 0 | AI8: {=INDEX($AZ$16:$BL$19,MATCH(LARGE($BL$16:$BL$19,2),$BL$16:$BL$19,0),6)} -> 0 | AJ8: {=INDEX($AZ$16:$BL$19,MATCH(LARGE($BL$16:$BL$19,2),$BL$16:$BL$19,0),7)} -> 0 | AK8: {=INDEX($AZ$16:$BL$19,MATCH(LARGE($BL$16:$BL$19,2),$BL$16:$BL$19,0),8)} -> 0 | AL8: {=INDEX($AZ$16:$BL$19,MATCH(LARGE($BL$16:$BL$19,2),$BL$16:$BL$19,0),9)} -> 0 | AM8: {=INDEX($AZ$16:$BL$19,MATCH(LARGE($BL$16:$BL$19,2),$BL$16:$BL$19,0),10)} -> 0 | AN8: {=INDEX($AZ$16:$BL$19,MATCH(LARGE($BL$16:$BL$19,2),$BL$16:$BL$19,0),11)} -> 0 | AO8: {=INDEX($AZ$16:$BL$19,MATCH(LARGE($BL$16:$BL$19,2),$BL$16:$BL$19,0),12)} -> 0 | AZ8: Czechia | BA8: 🇨🇿 | BB8: =SUMPRODUCT(('DU DOAN'!$B$4:$B$107="Vòng bảng")*('DU DOAN'!$D$4:$D$107="A")*ISNUMBER('DU DOAN'!$K$4:$K$107)*ISNUMBER('DU DOAN'!$L$4:$L$107)*(('DU DOAN'!$H$4:$H$107="Czechia")+('DU DOAN'!$I$4:$I$107="Czechia"))) -> 0 | BC8: =SUMPRODUCT(('DU DOAN'!$B$4:$B$107="Vòng bảng")*('DU DOAN'!$D$4:$D$107="A")*ISNUMBER('DU DOAN'!$K$4:$K$107)*ISNUMBER('DU DOAN'!$L$4:$L$107)*(('DU DOAN'!$H$4:$H$107="Czechia")*('DU DOAN'!$K$4:$K$107>'DU DOAN'!$L$4:$L$107)+('DU DOAN'!$I$4:$I$107="Czechia")*('DU DOAN'!$L$4:$L$107>'DU DOAN'!$K$4:$K$107))) -> 0 | BD8: =SUMPRODUCT(('DU DOAN'!$B$4:$B$107="Vòng bảng")*('DU DOAN'!$D$4:$D$107="A")*ISNUMBER('DU DOAN'!$K$4:$K$107)*ISNUMBER('DU DOAN'!$L$4:$L$107)*(('DU DOAN'!$H$4:$H$107="Czechia")*('DU DOAN'!$K$4:$K$107='DU DOAN'!$L$4:$L$107)+('DU DOAN'!$I$4:$I$107="Czechia")*('DU DOAN'!$K$4:$K$107='DU DOAN'!$L$4:$L$107))) -> 0 | BE8: =SUMPRODUCT(('DU DOAN'!$B$4:$B$107="Vòng bảng")*('DU DOAN'!$D$4:$D$107="A")*ISNUMBER('DU DOAN'!$K$4:$K$107)*ISNUMBER('DU DOAN'!$L$4:$L$107)*(('DU DOAN'!$H$4:$H$107="Czechia")*('DU DOAN'!$K$4:$K$107<'DU DOAN'!$L$4:$L$107)+('DU DOAN'!$I$4:$I$107="Czechia")*('DU DOAN'!$L$4:$L$107<'DU DOAN'!$K$4:$K$107))) -> 0 | BF8: =SUMPRODUCT(('DU DOAN'!$B$4:$B$107="Vòng bảng")*('DU DOAN'!$D$4:$D$107="A")*ISNUMBER('DU DOAN'!$K$4:$K$107)*ISNUMBER('DU DOAN'!$L$4:$L$107)*(('DU DOAN'!$H$4:$H$107="Czechia")*'DU DOAN'!$K$4:$K$107+('DU DOAN'!$I$4:$I$107="Czechia")*'DU DOAN'!$L$4:$L$107)) -> 0 | BG8: =SUMPRODUCT(('DU DOAN'!$B$4:$B$107="Vòng bảng")*('DU DOAN'!$D$4:$D$107="A")*ISNUMBER('DU DOAN'!$K$4:$K$107)*ISNUMBER('DU DOAN'!$L$4:$L$107)*(('DU DOAN'!$H$4:$H$107="Czechia")*'DU DOAN'!$L$4:$L$107+('DU DOAN'!$I$4:$I$107="Czechia")*'DU DOAN'!$K$4:$K$107)) -> 0 | BH8: =BF8-BG8 -> 0 | BI8: =SUMPRODUCT(IFERROR((#REF!="Czechia")*#REF!,0))+SUMPRODUCT(IFERROR((#REF!="Czechia")*#REF!,0)) -> 0 | BJ8: =SUMPRODUCT(IFERROR((#REF!="Czechia")*#REF!,0))+SUMPRODUCT(IFERROR((#REF!="Czechia")*#REF!,0)) -> 0 | BK8: =3*BC8+BD8 -> 0 | BL8: =BK8*1000000+BH8*10000+BF8*100+2 -> 2
A9: 3 | B9: {=INDEX($BA$6:$BA$9,MATCH(LARGE($BL$6:$BL$9,3),$BL$6:$BL$9,0))} -> 🇨🇿 | C9: {=INDEX($AZ$6:$AZ$9,MATCH(LARGE($BL$6:$BL$9,3),$BL$6:$BL$9,0))} -> Czechia | D9: {=INDEX($AZ$6:$BL$9,MATCH(LARGE($BL$6:$BL$9,3),$BL$6:$BL$9,0),3)} -> 0 | E9: {=INDEX($AZ$6:$BL$9,MATCH(LARGE($BL$6:$BL$9,3),$BL$6:$BL$9,0),4)} -> 0 | F9: {=INDEX($AZ$6:$BL$9,MATCH(LARGE($BL$6:$BL$9,3),$BL$6:$BL$9,0),5)} -> 0 | G9: {=INDEX($AZ$6:$BL$9,MATCH(LARGE($BL$6:$BL$9,3),$BL$6:$BL$9,0),6)} -> 0 | H9: {=INDEX($AZ$6:$BL$9,MATCH(LARGE($BL$6:$BL$9,3),$BL$6:$BL$9,0),7)} -> 0 | I9: {=INDEX($AZ$6:$BL$9,MATCH(LARGE($BL$6:$BL$9,3),$BL$6:$BL$9,0),8)} -> 0 | J9: {=INDEX($AZ$6:$BL$9,MATCH(LARGE($BL$6:$BL$9,3),$BL$6:$BL$9,0),9)} -> 0 | K9: {=INDEX($AZ$6:$BL$9,MATCH(LARGE($BL$6:$BL$9,3),$BL$6:$BL$9,0),10)} -> 0 | L9: {=INDEX($AZ$6:$BL$9,MATCH(LARGE($BL$6:$BL$9,3),$BL$6:$BL$9,0),11)} -> 0 | M9: {=INDEX($AZ$6:$BL$9,MATCH(LARGE($BL$6:$BL$9,3),$BL$6:$BL$9,0),12)} -> 0 | O9: 3 | P9: {=INDEX($BA$11:$BA$14,MATCH(LARGE($BL$11:$BL$14,3),$BL$11:$BL$14,0))} -> 🇧🇦 | Q9: {=INDEX($AZ$11:$AZ$14,MATCH(LARGE($BL$11:$BL$14,3),$BL$11:$BL$14,0))} -> Bosnia & Herzegovina | R9: {=INDEX($AZ$11:$BL$14,MATCH(LARGE($BL$11:$BL$14,3),$BL$11:$BL$14,0),3)} -> 0 | S9: {=INDEX($AZ$11:$BL$14,MATCH(LARGE($BL$11:$BL$14,3),$BL$11:$BL$14,0),4)} -> 0 | T9: {=INDEX($AZ$11:$BL$14,MATCH(LARGE($BL$11:$BL$14,3),$BL$11:$BL$14,0),5)} -> 0 | U9: {=INDEX($AZ$11:$BL$14,MATCH(LARGE($BL$11:$BL$14,3),$BL$11:$BL$14,0),6)} -> 0 | V9: {=INDEX($AZ$11:$BL$14,MATCH(LARGE($BL$11:$BL$14,3),$BL$11:$BL$14,0),7)} -> 0 | W9: {=INDEX($AZ$11:$BL$14,MATCH(LARGE($BL$11:$BL$14,3),$BL$11:$BL$14,0),8)} -> 0 | X9: {=INDEX($AZ$11:$BL$14,MATCH(LARGE($BL$11:$BL$14,3),$BL$11:$BL$14,0),9)} -> 0 | Y9: {=INDEX($AZ$11:$BL$14,MATCH(LARGE($BL$11:$BL$14,3),$BL$11:$BL$14,0),10)} -> 0 | Z9: {=INDEX($AZ$11:$BL$14,MATCH(LARGE($BL$11:$BL$14,3),$BL$11:$BL$14,0),11)} -> 0 | AA9: {=INDEX($AZ$11:$BL$14,MATCH(LARGE($BL$11:$BL$14,3),$BL$11:$BL$14,0),12)} -> 0 | AC9: 3 | AD9: {=INDEX($BA$16:$BA$19,MATCH(LARGE($BL$16:$BL$19,3),$BL$16:$BL$19,0))} -> 🇲🇦 | AE9: {=INDEX($AZ$16:$AZ$19,MATCH(LARGE($BL$16:$BL$19,3),$BL$16:$BL$19,0))} -> Morocco | AF9: {=INDEX($AZ$16:$BL$19,MATCH(LARGE($BL$16:$BL$19,3),$BL$16:$BL$19,0),3)} -> 0 | AG9: {=INDEX($AZ$16:$BL$19,MATCH(LARGE($BL$16:$BL$19,3),$BL$16:$BL$19,0),4)} -> 0 | AH9: {=INDEX($AZ$16:$BL$19,MATCH(LARGE($BL$16:$BL$19,3),$BL$16:$BL$19,0),5)} -> 0 | AI9: {=INDEX($AZ$16:$BL$19,MATCH(LARGE($BL$16:$BL$19,3),$BL$16:$BL$19,0),6)} -> 0 | AJ9: {=INDEX($AZ$16:$BL$19,MATCH(LARGE($BL$16:$BL$19,3),$BL$16:$BL$19,0),7)} -> 0 | AK9: {=INDEX($AZ$16:$BL$19,MATCH(LARGE($BL$16:$BL$19,3),$BL$16:$BL$19,0),8)} -> 0 | AL9: {=INDEX($AZ$16:$BL$19,MATCH(LARGE($BL$16:$BL$19,3),$BL$16:$BL$19,0),9)} -> 0 | AM9: {=INDEX($AZ$16:$BL$19,MATCH(LARGE($BL$16:$BL$19,3),$BL$16:$BL$19,0),10)} -> 0 | AN9: {=INDEX($AZ$16:$BL$19,MATCH(LARGE($BL$16:$BL$19,3),$BL$16:$BL$19,0),11)} -> 0 | AO9: {=INDEX($AZ$16:$BL$19,MATCH(LARGE($BL$16:$BL$19,3),$BL$16:$BL$19,0),12)} -> 0 | AZ9: South Africa | BA9: 🇿🇦 | BB9: =SUMPRODUCT(('DU DOAN'!$B$4:$B$107="Vòng bảng")*('DU DOAN'!$D$4:$D$107="A")*ISNUMBER('DU DOAN'!$K$4:$K$107)*ISNUMBER('DU DOAN'!$L$4:$L$107)*(('DU DOAN'!$H$4:$H$107="South Africa")+('DU DOAN'!$I$4:$I$107="South Africa"))) -> 0 | BC9: =SUMPRODUCT(('DU DOAN'!$B$4:$B$107="Vòng bảng")*('DU DOAN'!$D$4:$D$107="A")*ISNUMBER('DU DOAN'!$K$4:$K$107)*ISNUMBER('DU DOAN'!$L$4:$L$107)*(('DU DOAN'!$H$4:$H$107="South Africa")*('DU DOAN'!$K$4:$K$107>'DU DOAN'!$L$4:$L$107)+('DU DOAN'!$I$4:$I$107="South Africa")*('DU DOAN'!$L$4:$L$107>'DU DOAN'!$K$4:$K$107))) -> 0 | BD9: =SUMPRODUCT(('DU DOAN'!$B$4:$B$107="Vòng bảng")*('DU DOAN'!$D$4:$D$107="A")*ISNUMBER('DU DOAN'!$K$4:$K$107)*ISNUMBER('DU DOAN'!$L$4:$L$107)*(('DU DOAN'!$H$4:$H$107="South Africa")*('DU DOAN'!$K$4:$K$107='DU DOAN'!$L$4:$L$107)+('DU DOAN'!$I$4:$I$107="South Africa")*('DU DOAN'!$K$4:$K$107='DU DOAN'!$L$4:$L$107))) -> 0 | BE9: =SUMPRODUCT(('DU DOAN'!$B$4:$B$107="Vòng bảng")*('DU DOAN'!$D$4:$D$107="A")*ISNUMBER('DU DOAN'!$K$4:$K$107)*ISNUMBER('DU DOAN'!$L$4:$L$107)*(('DU DOAN'!$H$4:$H$107="South Africa")*('DU DOAN'!$K$4:$K$107<'DU DOAN'!$L$4:$L$107)+('DU DOAN'!$I$4:$I$107="South Africa")*('DU DOAN'!$L$4:$L$107<'DU DOAN'!$K$4:$K$107))) -> 0 | BF9: =SUMPRODUCT(('DU DOAN'!$B$4:$B$107="Vòng bảng")*('DU DOAN'!$D$4:$D$107="A")*ISNUMBER('DU DOAN'!$K$4:$K$107)*ISNUMBER('DU DOAN'!$L$4:$L$107)*(('DU DOAN'!$H$4:$H$107="South Africa")*'DU DOAN'!$K$4:$K$107+('DU DOAN'!$I$4:$I$107="South Africa")*'DU DOAN'!$L$4:$L$107)) -> 0 | BG9: =SUMPRODUCT(('DU DOAN'!$B$4:$B$107="Vòng bảng")*('DU DOAN'!$D$4:$D$107="A")*ISNUMBER('DU DOAN'!$K$4:$K$107)*ISNUMBER('DU DOAN'!$L$4:$L$107)*(('DU DOAN'!$H$4:$H$107="South Africa")*'DU DOAN'!$L$4:$L$107+('DU DOAN'!$I$4:$I$107="South Africa")*'DU DOAN'!$K$4:$K$107)) -> 0 | BH9: =BF9-BG9 -> 0 | BI9: =SUMPRODUCT(IFERROR((#REF!="South Africa")*#REF!,0))+SUMPRODUCT(IFERROR((#REF!="South Africa")*#REF!,0)) -> 0 | BJ9: =SUMPRODUCT(IFERROR((#REF!="South Africa")*#REF!,0))+SUMPRODUCT(IFERROR((#REF!="South Africa")*#REF!,0)) -> 0 | BK9: =3*BC9+BD9 -> 0 | BL9: =BK9*1000000+BH9*10000+BF9*100+1 -> 1
A10: 4 | B10: {=INDEX($BA$6:$BA$9,MATCH(LARGE($BL$6:$BL$9,4),$BL$6:$BL$9,0))} -> 🇿🇦 | C10: {=INDEX($AZ$6:$AZ$9,MATCH(LARGE($BL$6:$BL$9,4),$BL$6:$BL$9,0))} -> South Africa | D10: {=INDEX($AZ$6:$BL$9,MATCH(LARGE($BL$6:$BL$9,4),$BL$6:$BL$9,0),3)} -> 0 | E10: {=INDEX($AZ$6:$BL$9,MATCH(LARGE($BL$6:$BL$9,4),$BL$6:$BL$9,0),4)} -> 0 | F10: {=INDEX($AZ$6:$BL$9,MATCH(LARGE($BL$6:$BL$9,4),$BL$6:$BL$9,0),5)} -> 0 | G10: {=INDEX($AZ$6:$BL$9,MATCH(LARGE($BL$6:$BL$9,4),$BL$6:$BL$9,0),6)} -> 0 | H10: {=INDEX($AZ$6:$BL$9,MATCH(LARGE($BL$6:$BL$9,4),$BL$6:$BL$9,0),7)} -> 0 | I10: {=INDEX($AZ$6:$BL$9,MATCH(LARGE($BL$6:$BL$9,4),$BL$6:$BL$9,0),8)} -> 0 | J10: {=INDEX($AZ$6:$BL$9,MATCH(LARGE($BL$6:$BL$9,4),$BL$6:$BL$9,0),9)} -> 0 | K10: {=INDEX($AZ$6:$BL$9,MATCH(LARGE($BL$6:$BL$9,4),$BL$6:$BL$9,0),10)} -> 0 | L10: {=INDEX($AZ$6:$BL$9,MATCH(LARGE($BL$6:$BL$9,4),$BL$6:$BL$9,0),11)} -> 0 | M10: {=INDEX($AZ$6:$BL$9,MATCH(LARGE($BL$6:$BL$9,4),$BL$6:$BL$9,0),12)} -> 0 | O10: 4 | P10: {=INDEX($BA$11:$BA$14,MATCH(LARGE($BL$11:$BL$14,4),$BL$11:$BL$14,0))} -> 🇶🇦 | Q10: {=INDEX($AZ$11:$AZ$14,MATCH(LARGE($BL$11:$BL$14,4),$BL$11:$BL$14,0))} -> Qatar | R10: {=INDEX($AZ$11:$BL$14,MATCH(LARGE($BL$11:$BL$14,4),$BL$11:$BL$14,0),3)} -> 0 | S10: {=INDEX($AZ$11:$BL$14,MATCH(LARGE($BL$11:$BL$14,4),$BL$11:$BL$14,0),4)} -> 0 | T10: {=INDEX($AZ$11:$BL$14,MATCH(LARGE($BL$11:$BL$14,4),$BL$11:$BL$14,0),5)} -> 0 | U10: {=INDEX($AZ$11:$BL$14,MATCH(LARGE($BL$11:$BL$14,4),$BL$11:$BL$14,0),6)} -> 0 | V10: {=INDEX($AZ$11:$BL$14,MATCH(LARGE($BL$11:$BL$14,4),$BL$11:$BL$14,0),7)} -> 0 | W10: {=INDEX($AZ$11:$BL$14,MATCH(LARGE($BL$11:$BL$14,4),$BL$11:$BL$14,0),8)} -> 0 | X10: {=INDEX($AZ$11:$BL$14,MATCH(LARGE($BL$11:$BL$14,4),$BL$11:$BL$14,0),9)} -> 0 | Y10: {=INDEX($AZ$11:$BL$14,MATCH(LARGE($BL$11:$BL$14,4),$BL$11:$BL$14,0),10)} -> 0 | Z10: {=INDEX($AZ$11:$BL$14,MATCH(LARGE($BL$11:$BL$14,4),$BL$11:$BL$14,0),11)} -> 0 | AA10: {=INDEX($AZ$11:$BL$14,MATCH(LARGE($BL$11:$BL$14,4),$BL$11:$BL$14,0),12)} -> 0 | AC10: 4 | AD10: {=INDEX($BA$16:$BA$19,MATCH(LARGE($BL$16:$BL$19,4),$BL$16:$BL$19,0))} -> 🇭🇹 | AE10: {=INDEX($AZ$16:$AZ$19,MATCH(LARGE($BL$16:$BL$19,4),$BL$16:$BL$19,0))} -> Haiti | AF10: {=INDEX($AZ$16:$BL$19,MATCH(LARGE($BL$16:$BL$19,4),$BL$16:$BL$19,0),3)} -> 0 | AG10: {=INDEX($AZ$16:$BL$19,MATCH(LARGE($BL$16:$BL$19,4),$BL$16:$BL$19,0),4)} -> 0 | AH10: {=INDEX($AZ$16:$BL$19,MATCH(LARGE($BL$16:$BL$19,4),$BL$16:$BL$19,0),5)} -> 0 | AI10: {=INDEX($AZ$16:$BL$19,MATCH(LARGE($BL$16:$BL$19,4),$BL$16:$BL$19,0),6)} -> 0 | AJ10: {=INDEX($AZ$16:$BL$19,MATCH(LARGE($BL$16:$BL$19,4),$BL$16:$BL$19,0),7)} -> 0 | AK10: {=INDEX($AZ$16:$BL$19,MATCH(LARGE($BL$16:$BL$19,4),$BL$16:$BL$19,0),8)} -> 0 | AL10: {=INDEX($AZ$16:$BL$19,MATCH(LARGE($BL$16:$BL$19,4),$BL$16:$BL$19,0),9)} -> 0 | AM10: {=INDEX($AZ$16:$BL$19,MATCH(LARGE($BL$16:$BL$19,4),$BL$16:$BL$19,0),10)} -> 0 | AN10: {=INDEX($AZ$16:$BL$19,MATCH(LARGE($BL$16:$BL$19,4),$BL$16:$BL$19,0),11)} -> 0 | AO10: {=INDEX($AZ$16:$BL$19,MATCH(LARGE($BL$16:$BL$19,4),$BL$16:$BL$19,0),12)} -> 0
AY11: B | AZ11: Canada | BA11: 🇨🇦 | BB11: =SUMPRODUCT(('DU DOAN'!$B$4:$B$107="Vòng bảng")*('DU DOAN'!$D$4:$D$107="B")*ISNUMBER('DU DOAN'!$K$4:$K$107)*ISNUMBER('DU DOAN'!$L$4:$L$107)*(('DU DOAN'!$H$4:$H$107="Canada")+('DU DOAN'!$I$4:$I$107="Canada"))) -> 0 | BC11: =SUMPRODUCT(('DU DOAN'!$B$4:$B$107="Vòng bảng")*('DU DOAN'!$D$4:$D$107="B")*ISNUMBER('DU DOAN'!$K$4:$K$107)*ISNUMBER('DU DOAN'!$L$4:$L$107)*(('DU DOAN'!$H$4:$H$107="Canada")*('DU DOAN'!$K$4:$K$107>'DU DOAN'!$L$4:$L$107)+('DU DOAN'!$I$4:$I$107="Canada")*('DU DOAN'!$L$4:$L$107>'DU DOAN'!$K$4:$K$107))) -> 0 | BD11: =SUMPRODUCT(('DU DOAN'!$B$4:$B$107="Vòng bảng")*('DU DOAN'!$D$4:$D$107="B")*ISNUMBER('DU DOAN'!$K$4:$K$107)*ISNUMBER('DU DOAN'!$L$4:$L$107)*(('DU DOAN'!$H$4:$H$107="Canada")*('DU DOAN'!$K$4:$K$107='DU DOAN'!$L$4:$L$107)+('DU DOAN'!$I$4:$I$107="Canada")*('DU DOAN'!$K$4:$K$107='DU DOAN'!$L$4:$L$107))) -> 0 | BE11: =SUMPRODUCT(('DU DOAN'!$B$4:$B$107="Vòng bảng")*('DU DOAN'!$D$4:$D$107="B")*ISNUMBER('DU DOAN'!$K$4:$K$107)*ISNUMBER('DU DOAN'!$L$4:$L$107)*(('DU DOAN'!$H$4:$H$107="Canada")*('DU DOAN'!$K$4:$K$107<'DU DOAN'!$L$4:$L$107)+('DU DOAN'!$I$4:$I$107="Canada")*('DU DOAN'!$L$4:$L$107<'DU DOAN'!$K$4:$K$107))) -> 0 | BF11: =SUMPRODUCT(('DU DOAN'!$B$4:$B$107="Vòng bảng")*('DU DOAN'!$D$4:$D$107="B")*ISNUMBER('DU DOAN'!$K$4:$K$107)*ISNUMBER('DU DOAN'!$L$4:$L$107)*(('DU DOAN'!$H$4:$H$107="Canada")*'DU DOAN'!$K$4:$K$107+('DU DOAN'!$I$4:$I$107="Canada")*'DU DOAN'!$L$4:$L$107)) -> 0 | BG11: =SUMPRODUCT(('DU DOAN'!$B$4:$B$107="Vòng bảng")*('DU DOAN'!$D$4:$D$107="B")*ISNUMBER('DU DOAN'!$K$4:$K$107)*ISNUMBER('DU DOAN'!$L$4:$L$107)*(('DU DOAN'!$H$4:$H$107="Canada")*'DU DOAN'!$L$4:$L$107+('DU DOAN'!$I$4:$I$107="Canada")*'DU DOAN'!$K$4:$K$107)) -> 0 | BH11: =BF11-BG11 -> 0 | BI11: =SUMPRODUCT(IFERROR((#REF!="Canada")*#REF!,0))+SUMPRODUCT(IFERROR((#REF!="Canada")*#REF!,0)) -> 0 | BJ11: =SUMPRODUCT(IFERROR((#REF!="Canada")*#REF!,0))+SUMPRODUCT(IFERROR((#REF!="Canada")*#REF!,0)) -> 0 | BK11: =3*BC11+BD11 -> 0 | BL11: =BK11*1000000+BH11*10000+BF11*100+4 -> 4
A12: BẢNG D | O12: BẢNG E | AC12: BẢNG F | AZ12: Switzerland | BA12: 🇨🇭 | BB12: =SUMPRODUCT(('DU DOAN'!$B$4:$B$107="Vòng bảng")*('DU DOAN'!$D$4:$D$107="B")*ISNUMBER('DU DOAN'!$K$4:$K$107)*ISNUMBER('DU DOAN'!$L$4:$L$107)*(('DU DOAN'!$H$4:$H$107="Switzerland")+('DU DOAN'!$I$4:$I$107="Switzerland"))) -> 0 | BC12: =SUMPRODUCT(('DU DOAN'!$B$4:$B$107="Vòng bảng")*('DU DOAN'!$D$4:$D$107="B")*ISNUMBER('DU DOAN'!$K$4:$K$107)*ISNUMBER('DU DOAN'!$L$4:$L$107)*(('DU DOAN'!$H$4:$H$107="Switzerland")*('DU DOAN'!$K$4:$K$107>'DU DOAN'!$L$4:$L$107)+('DU DOAN'!$I$4:$I$107="Switzerland")*('DU DOAN'!$L$4:$L$107>'DU DOAN'!$K$4:$K$107))) -> 0 | BD12: =SUMPRODUCT(('DU DOAN'!$B$4:$B$107="Vòng bảng")*('DU DOAN'!$D$4:$D$107="B")*ISNUMBER('DU DOAN'!$K$4:$K$107)*ISNUMBER('DU DOAN'!$L$4:$L$107)*(('DU DOAN'!$H$4:$H$107="Switzerland")*('DU DOAN'!$K$4:$K$107='DU DOAN'!$L$4:$L$107)+('DU DOAN'!$I$4:$I$107="Switzerland")*('DU DOAN'!$K$4:$K$107='DU DOAN'!$L$4:$L$107))) -> 0 | BE12: =SUMPRODUCT(('DU DOAN'!$B$4:$B$107="Vòng bảng")*('DU DOAN'!$D$4:$D$107="B")*ISNUMBER('DU DOAN'!$K$4:$K$107)*ISNUMBER('DU DOAN'!$L$4:$L$107)*(('DU DOAN'!$H$4:$H$107="Switzerland")*('DU DOAN'!$K$4:$K$107<'DU DOAN'!$L$4:$L$107)+('DU DOAN'!$I$4:$I$107="Switzerland")*('DU DOAN'!$L$4:$L$107<'DU DOAN'!$K$4:$K$107))) -> 0 | BF12: =SUMPRODUCT(('DU DOAN'!$B$4:$B$107="Vòng bảng")*('DU DOAN'!$D$4:$D$107="B")*ISNUMBER('DU DOAN'!$K$4:$K$107)*ISNUMBER('DU DOAN'!$L$4:$L$107)*(('DU DOAN'!$H$4:$H$107="Switzerland")*'DU DOAN'!$K$4:$K$107+('DU DOAN'!$I$4:$I$107="Switzerland")*'DU DOAN'!$L$4:$L$107)) -> 0 | BG12: =SUMPRODUCT(('DU DOAN'!$B$4:$B$107="Vòng bảng")*('DU DOAN'!$D$4:$D$107="B")*ISNUMBER('DU DOAN'!$K$4:$K$107)*ISNUMBER('DU DOAN'!$L$4:$L$107)*(('DU DOAN'!$H$4:$H$107="Switzerland")*'DU DOAN'!$L$4:$L$107+('DU DOAN'!$I$4:$I$107="Switzerland")*'DU DOAN'!$K$4:$K$107)) -> 0 | BH12: =BF12-BG12 -> 0 | BI12: =SUMPRODUCT(IFERROR((#REF!="Switzerland")*#REF!,0))+SUMPRODUCT(IFERROR((#REF!="Switzerland")*#REF!,0)) -> 0 | BJ12: =SUMPRODUCT(IFERROR((#REF!="Switzerland")*#REF!,0))+SUMPRODUCT(IFERROR((#REF!="Switzerland")*#REF!,0)) -> 0 | BK12: =3*BC12+BD12 -> 0 | BL12: =BK12*1000000+BH12*10000+BF12*100+3 -> 3
A13: # | B13: 🏴 | C13: Đội tuyển | D13: Đá | E13: T | F13: H | G13: B | H13: GF | I13: GA | J13: GD | K13: 🟨 | L13: 🟥 | M13: Pts | O13: # | P13: 🏴 | Q13: Đội tuyển | R13: Đá | S13: T | T13: H | U13: B | V13: GF | W13: GA | X13: GD | Y13: 🟨 | Z13: 🟥 | AA13: Pts | AC13: # | AD13: 🏴 | AE13: Đội tuyển | AF13: Đá | AG13: T | AH13: H | AI13: B | AJ13: GF | AK13: GA | AL13: GD | AM13: 🟨 | AN13: 🟥 | AO13: Pts | AZ13: Bosnia & Herzegovina | BA13: 🇧🇦 | BB13: =SUMPRODUCT(('DU DOAN'!$B$4:$B$107="Vòng bảng")*('DU DOAN'!$D$4:$D$107="B")*ISNUMBER('DU DOAN'!$K$4:$K$107)*ISNUMBER('DU DOAN'!$L$4:$L$107)*(('DU DOAN'!$H$4:$H$107="Bosnia & Herzegovina")+('DU DOAN'!$I$4:$I$107="Bosnia & Herzegovina"))) -> 0 | BC13: =SUMPRODUCT(('DU DOAN'!$B$4:$B$107="Vòng bảng")*('DU DOAN'!$D$4:$D$107="B")*ISNUMBER('DU DOAN'!$K$4:$K$107)*ISNUMBER('DU DOAN'!$L$4:$L$107)*(('DU DOAN'!$H$4:$H$107="Bosnia & Herzegovina")*('DU DOAN'!$K$4:$K$107>'DU DOAN'!$L$4:$L$107)+('DU DOAN'!$I$4:$I$107="Bosnia & Herzegovina")*('DU DOAN'!$L$4:$L$107>'DU DOAN'!$K$4:$K$107))) -> 0 | BD13: =SUMPRODUCT(('DU DOAN'!$B$4:$B$107="Vòng bảng")*('DU DOAN'!$D$4:$D$107="B")*ISNUMBER('DU DOAN'!$K$4:$K$107)*ISNUMBER('DU DOAN'!$L$4:$L$107)*(('DU DOAN'!$H$4:$H$107="Bosnia & Herzegovina")*('DU DOAN'!$K$4:$K$107='DU DOAN'!$L$4:$L$107)+('DU DOAN'!$I$4:$I$107="Bosnia & Herzegovina")*('DU DOAN'!$K$4:$K$107='DU DOAN'!$L$4:$L$107))) -> 0 | BE13: =SUMPRODUCT(('DU DOAN'!$B$4:$B$107="Vòng bảng")*('DU DOAN'!$D$4:$D$107="B")*ISNUMBER('DU DOAN'!$K$4:$K$107)*ISNUMBER('DU DOAN'!$L$4:$L$107)*(('DU DOAN'!$H$4:$H$107="Bosnia & Herzegovina")*('DU DOAN'!$K$4:$K$107<'DU DOAN'!$L$4:$L$107)+('DU DOAN'!$I$4:$I$107="Bosnia & Herzegovina")*('DU DOAN'!$L$4:$L$107<'DU DOAN'!$K$4:$K$107))) -> 0 | BF13: =SUMPRODUCT(('DU DOAN'!$B$4:$B$107="Vòng bảng")*('DU DOAN'!$D$4:$D$107="B")*ISNUMBER('DU DOAN'!$K$4:$K$107)*ISNUMBER('DU DOAN'!$L$4:$L$107)*(('DU DOAN'!$H$4:$H$107="Bosnia & Herzegovina")*'DU DOAN'!$K$4:$K$107+('DU DOAN'!$I$4:$I$107="Bosnia & Herzegovina")*'DU DOAN'!$L$4:$L$107)) -> 0 | BG13: =SUMPRODUCT(('DU DOAN'!$B$4:$B$107="Vòng bảng")*('DU DOAN'!$D$4:$D$107="B")*ISNUMBER('DU DOAN'!$K$4:$K$107)*ISNUMBER('DU DOAN'!$L$4:$L$107)*(('DU DOAN'!$H$4:$H$107="Bosnia & Herzegovina")*'DU DOAN'!$L$4:$L$107+('DU DOAN'!$I$4:$I$107="Bosnia & Herzegovina")*'DU DOAN'!$K$4:$K$107)) -> 0 | BH13: =BF13-BG13 -> 0 | BI13: =SUMPRODUCT(IFERROR((#REF!="Bosnia & Herzegovina")*#REF!,0))+SUMPRODUCT(IFERROR((#REF!="Bosnia & Herzegovina")*#REF!,0)) -> 0 | BJ13: =SUMPRODUCT(IFERROR((#REF!="Bosnia & Herzegovina")*#REF!,0))+SUMPRODUCT(IFERROR((#REF!="Bosnia & Herzegovina")*#REF!,0)) -> 0 | BK13: =3*BC13+BD13 -> 0 | BL13: =BK13*1000000+BH13*10000+BF13*100+2 -> 2
A14: 1 | B14: {=INDEX($BA$21:$BA$24,MATCH(LARGE($BL$21:$BL$24,1),$BL$21:$BL$24,0))} -> 🇺🇸 | C14: {=INDEX($AZ$21:$AZ$24,MATCH(LARGE($BL$21:$BL$24,1),$BL$21:$BL$24,0))} -> United States | D14: {=INDEX($AZ$21:$BL$24,MATCH(LARGE($BL$21:$BL$24,1),$BL$21:$BL$24,0),3)} -> 0 | E14: {=INDEX($AZ$21:$BL$24,MATCH(LARGE($BL$21:$BL$24,1),$BL$21:$BL$24,0),4)} -> 0 | F14: {=INDEX($AZ$21:$BL$24,MATCH(LARGE($BL$21:$BL$24,1),$BL$21:$BL$24,0),5)} -> 0 | G14: {=INDEX($AZ$21:$BL$24,MATCH(LARGE($BL$21:$BL$24,1),$BL$21:$BL$24,0),6)} -> 0 | H14: {=INDEX($AZ$21:$BL$24,MATCH(LARGE($BL$21:$BL$24,1),$BL$21:$BL$24,0),7)} -> 0 | I14: {=INDEX($AZ$21:$BL$24,MATCH(LARGE($BL$21:$BL$24,1),$BL$21:$BL$24,0),8)} -> 0 | J14: {=INDEX($AZ$21:$BL$24,MATCH(LARGE($BL$21:$BL$24,1),$BL$21:$BL$24,0),9)} -> 0 | K14: {=INDEX($AZ$21:$BL$24,MATCH(LARGE($BL$21:$BL$24,1),$BL$21:$BL$24,0),10)} -> 0 | L14: {=INDEX($AZ$21:$BL$24,MATCH(LARGE($BL$21:$BL$24,1),$BL$21:$BL$24,0),11)} -> 0 | M14: {=INDEX($AZ$21:$BL$24,MATCH(LARGE($BL$21:$BL$24,1),$BL$21:$BL$24,0),12)} -> 0 | O14: 1 | P14: {=INDEX($BA$26:$BA$29,MATCH(LARGE($BL$26:$BL$29,1),$BL$26:$BL$29,0))} -> 🇩🇪 | Q14: {=INDEX($AZ$26:$AZ$29,MATCH(LARGE($BL$26:$BL$29,1),$BL$26:$BL$29,0))} -> Germany | R14: {=INDEX($AZ$26:$BL$29,MATCH(LARGE($BL$26:$BL$29,1),$BL$26:$BL$29,0),3)} -> 0 | S14: {=INDEX($AZ$26:$BL$29,MATCH(LARGE($BL$26:$BL$29,1),$BL$26:$BL$29,0),4)} -> 0 | T14: {=INDEX($AZ$26:$BL$29,MATCH(LARGE($BL$26:$BL$29,1),$BL$26:$BL$29,0),5)} -> 0 | U14: {=INDEX($AZ$26:$BL$29,MATCH(LARGE($BL$26:$BL$29,1),$BL$26:$BL$29,0),6)} -> 0 | V14: {=INDEX($AZ$26:$BL$29,MATCH(LARGE($BL$26:$BL$29,1),$BL$26:$BL$29,0),7)} -> 0 | W14: {=INDEX($AZ$26:$BL$29,MATCH(LARGE($BL$26:$BL$29,1),$BL$26:$BL$29,0),8)} -> 0 | X14: {=INDEX($AZ$26:$BL$29,MATCH(LARGE($BL$26:$BL$29,1),$BL$26:$BL$29,0),9)} -> 0 | Y14: {=INDEX($AZ$26:$BL$29,MATCH(LARGE($BL$26:$BL$29,1),$BL$26:$BL$29,0),10)} -> 0 | Z14: {=INDEX($AZ$26:$BL$29,MATCH(LARGE($BL$26:$BL$29,1),$BL$26:$BL$29,0),11)} -> 0 | AA14: {=INDEX($AZ$26:$BL$29,MATCH(LARGE($BL$26:$BL$29,1),$BL$26:$BL$29,0),12)} -> 0 | AC14: 1 | AD14: {=INDEX($BA$31:$BA$34,MATCH(LARGE($BL$31:$BL$34,1),$BL$31:$BL$34,0))} -> 🇳🇱 | AE14: {=INDEX($AZ$31:$AZ$34,MATCH(LARGE($BL$31:$BL$34,1),$BL$31:$BL$34,0))} -> Netherlands | AF14: {=INDEX($AZ$31:$BL$34,MATCH(LARGE($BL$31:$BL$34,1),$BL$31:$BL$34,0),3)} -> 0 | AG14: {=INDEX($AZ$31:$BL$34,MATCH(LARGE($BL$31:$BL$34,1),$BL$31:$BL$34,0),4)} -> 0 | AH14: {=INDEX($AZ$31:$BL$34,MATCH(LARGE($BL$31:$BL$34,1),$BL$31:$BL$34,0),5)} -> 0 | AI14: {=INDEX($AZ$31:$BL$34,MATCH(LARGE($BL$31:$BL$34,1),$BL$31:$BL$34,0),6)} -> 0 | AJ14: {=INDEX($AZ$31:$BL$34,MATCH(LARGE($BL$31:$BL$34,1),$BL$31:$BL$34,0),7)} -> 0 | AK14: {=INDEX($AZ$31:$BL$34,MATCH(LARGE($BL$31:$BL$34,1),$BL$31:$BL$34,0),8)} -> 0 | AL14: {=INDEX($AZ$31:$BL$34,MATCH(LARGE($BL$31:$BL$34,1),$BL$31:$BL$34,0),9)} -> 0 | AM14: {=INDEX($AZ$31:$BL$34,MATCH(LARGE($BL$31:$BL$34,1),$BL$31:$BL$34,0),10)} -> 0 | AN14: {=INDEX($AZ$31:$BL$34,MATCH(LARGE($BL$31:$BL$34,1),$BL$31:$BL$34,0),11)} -> 0 | AO14: {=INDEX($AZ$31:$BL$34,MATCH(LARGE($BL$31:$BL$34,1),$BL$31:$BL$34,0),12)} -> 0 | AZ14: Qatar | BA14: 🇶🇦 | BB14: =SUMPRODUCT(('DU DOAN'!$B$4:$B$107="Vòng bảng")*('DU DOAN'!$D$4:$D$107="B")*ISNUMBER('DU DOAN'!$K$4:$K$107)*ISNUMBER('DU DOAN'!$L$4:$L$107)*(('DU DOAN'!$H$4:$H$107="Qatar")+('DU DOAN'!$I$4:$I$107="Qatar"))) -> 0 | BC14: =SUMPRODUCT(('DU DOAN'!$B$4:$B$107="Vòng bảng")*('DU DOAN'!$D$4:$D$107="B")*ISNUMBER('DU DOAN'!$K$4:$K$107)*ISNUMBER('DU DOAN'!$L$4:$L$107)*(('DU DOAN'!$H$4:$H$107="Qatar")*('DU DOAN'!$K$4:$K$107>'DU DOAN'!$L$4:$L$107)+('DU DOAN'!$I$4:$I$107="Qatar")*('DU DOAN'!$L$4:$L$107>'DU DOAN'!$K$4:$K$107))) -> 0 | BD14: =SUMPRODUCT(('DU DOAN'!$B$4:$B$107="Vòng bảng")*('DU DOAN'!$D$4:$D$107="B")*ISNUMBER('DU DOAN'!$K$4:$K$107)*ISNUMBER('DU DOAN'!$L$4:$L$107)*(('DU DOAN'!$H$4:$H$107="Qatar")*('DU DOAN'!$K$4:$K$107='DU DOAN'!$L$4:$L$107)+('DU DOAN'!$I$4:$I$107="Qatar")*('DU DOAN'!$K$4:$K$107='DU DOAN'!$L$4:$L$107))) -> 0 | BE14: =SUMPRODUCT(('DU DOAN'!$B$4:$B$107="Vòng bảng")*('DU DOAN'!$D$4:$D$107="B")*ISNUMBER('DU DOAN'!$K$4:$K$107)*ISNUMBER('DU DOAN'!$L$4:$L$107)*(('DU DOAN'!$H$4:$H$107="Qatar")*('DU DOAN'!$K$4:$K$107<'DU DOAN'!$L$4:$L$107)+('DU DOAN'!$I$4:$I$107="Qatar")*('DU DOAN'!$L$4:$L$107<'DU DOAN'!$K$4:$K$107))) -> 0 | BF14: =SUMPRODUCT(('DU DOAN'!$B$4:$B$107="Vòng bảng")*('DU DOAN'!$D$4:$D$107="B")*ISNUMBER('DU DOAN'!$K$4:$K$107)*ISNUMBER('DU DOAN'!$L$4:$L$107)*(('DU DOAN'!$H$4:$H$107="Qatar")*'DU DOAN'!$K$4:$K$107+('DU DOAN'!$I$4:$I$107="Qatar")*'DU DOAN'!$L$4:$L$107)) -> 0 | BG14: =SUMPRODUCT(('DU DOAN'!$B$4:$B$107="Vòng bảng")*('DU DOAN'!$D$4:$D$107="B")*ISNUMBER('DU DOAN'!$K$4:$K$107)*ISNUMBER('DU DOAN'!$L$4:$L$107)*(('DU DOAN'!$H$4:$H$107="Qatar")*'DU DOAN'!$L$4:$L$107+('DU DOAN'!$I$4:$I$107="Qatar")*'DU DOAN'!$K$4:$K$107)) -> 0 | BH14: =BF14-BG14 -> 0 | BI14: =SUMPRODUCT(IFERROR((#REF!="Qatar")*#REF!,0))+SUMPRODUCT(IFERROR((#REF!="Qatar")*#REF!,0)) -> 0 | BJ14: =SUMPRODUCT(IFERROR((#REF!="Qatar")*#REF!,0))+SUMPRODUCT(IFERROR((#REF!="Qatar")*#REF!,0)) -> 0 | BK14: =3*BC14+BD14 -> 0 | BL14: =BK14*1000000+BH14*10000+BF14*100+1 -> 1
A15: 2 | B15: {=INDEX($BA$21:$BA$24,MATCH(LARGE($BL$21:$BL$24,2),$BL$21:$BL$24,0))} -> 🇹🇷 | C15: {=INDEX($AZ$21:$AZ$24,MATCH(LARGE($BL$21:$BL$24,2),$BL$21:$BL$24,0))} -> Türkiye | D15: {=INDEX($AZ$21:$BL$24,MATCH(LARGE($BL$21:$BL$24,2),$BL$21:$BL$24,0),3)} -> 0 | E15: {=INDEX($AZ$21:$BL$24,MATCH(LARGE($BL$21:$BL$24,2),$BL$21:$BL$24,0),4)} -> 0 | F15: {=INDEX($AZ$21:$BL$24,MATCH(LARGE($BL$21:$BL$24,2),$BL$21:$BL$24,0),5)} -> 0 | G15: {=INDEX($AZ$21:$BL$24,MATCH(LARGE($BL$21:$BL$24,2),$BL$21:$BL$24,0),6)} -> 0 | H15: {=INDEX($AZ$21:$BL$24,MATCH(LARGE($BL$21:$BL$24,2),$BL$21:$BL$24,0),7)} -> 0 | I15: {=INDEX($AZ$21:$BL$24,MATCH(LARGE($BL$21:$BL$24,2),$BL$21:$BL$24,0),8)} -> 0 | J15: {=INDEX($AZ$21:$BL$24,MATCH(LARGE($BL$21:$BL$24,2),$BL$21:$BL$24,0),9)} -> 0 | K15: {=INDEX($AZ$21:$BL$24,MATCH(LARGE($BL$21:$BL$24,2),$BL$21:$BL$24,0),10)} -> 0 | L15: {=INDEX($AZ$21:$BL$24,MATCH(LARGE($BL$21:$BL$24,2),$BL$21:$BL$24,0),11)} -> 0 | M15: {=INDEX($AZ$21:$BL$24,MATCH(LARGE($BL$21:$BL$24,2),$BL$21:$BL$24,0),12)} -> 0 | O15: 2 | P15: {=INDEX($BA$26:$BA$29,MATCH(LARGE($BL$26:$BL$29,2),$BL$26:$BL$29,0))} -> 🇨🇮 | Q15: {=INDEX($AZ$26:$AZ$29,MATCH(LARGE($BL$26:$BL$29,2),$BL$26:$BL$29,0))} -> Côte d'Ivoire | R15: {=INDEX($AZ$26:$BL$29,MATCH(LARGE($BL$26:$BL$29,2),$BL$26:$BL$29,0),3)} -> 0 | S15: {=INDEX($AZ$26:$BL$29,MATCH(LARGE($BL$26:$BL$29,2),$BL$26:$BL$29,0),4)} -> 0 | T15: {=INDEX($AZ$26:$BL$29,MATCH(LARGE($BL$26:$BL$29,2),$BL$26:$BL$29,0),5)} -> 0 | U15: {=INDEX($AZ$26:$BL$29,MATCH(LARGE($BL$26:$BL$29,2),$BL$26:$BL$29,0),6)} -> 0 | V15: {=INDEX($AZ$26:$BL$29,MATCH(LARGE($BL$26:$BL$29,2),$BL$26:$BL$29,0),7)} -> 0 | W15: {=INDEX($AZ$26:$BL$29,MATCH(LARGE($BL$26:$BL$29,2),$BL$26:$BL$29,0),8)} -> 0 | X15: {=INDEX($AZ$26:$BL$29,MATCH(LARGE($BL$26:$BL$29,2),$BL$26:$BL$29,0),9)} -> 0 | Y15: {=INDEX($AZ$26:$BL$29,MATCH(LARGE($BL$26:$BL$29,2),$BL$26:$BL$29,0),10)} -> 0 | Z15: {=INDEX($AZ$26:$BL$29,MATCH(LARGE($BL$26:$BL$29,2),$BL$26:$BL$29,0),11)} -> 0 | AA15: {=INDEX($AZ$26:$BL$29,MATCH(LARGE($BL$26:$BL$29,2),$BL$26:$BL$29,0),12)} -> 0 | AC15: 2 | AD15: {=INDEX($BA$31:$BA$34,MATCH(LARGE($BL$31:$BL$34,2),$BL$31:$BL$34,0))} -> 🇸🇪 | AE15: {=INDEX($AZ$31:$AZ$34,MATCH(LARGE($BL$31:$BL$34,2),$BL$31:$BL$34,0))} -> Sweden | AF15: {=INDEX($AZ$31:$BL$34,MATCH(LARGE($BL$31:$BL$34,2),$BL$31:$BL$34,0),3)} -> 0 | AG15: {=INDEX($AZ$31:$BL$34,MATCH(LARGE($BL$31:$BL$34,2),$BL$31:$BL$34,0),4)} -> 0 | AH15: {=INDEX($AZ$31:$BL$34,MATCH(LARGE($BL$31:$BL$34,2),$BL$31:$BL$34,0),5)} -> 0 | AI15: {=INDEX($AZ$31:$BL$34,MATCH(LARGE($BL$31:$BL$34,2),$BL$31:$BL$34,0),6)} -> 0 | AJ15: {=INDEX($AZ$31:$BL$34,MATCH(LARGE($BL$31:$BL$34,2),$BL$31:$BL$34,0),7)} -> 0 | AK15: {=INDEX($AZ$31:$BL$34,MATCH(LARGE($BL$31:$BL$34,2),$BL$31:$BL$34,0),8)} -> 0 | AL15: {=INDEX($AZ$31:$BL$34,MATCH(LARGE($BL$31:$BL$34,2),$BL$31:$BL$34,0),9)} -> 0 | AM15: {=INDEX($AZ$31:$BL$34,MATCH(LARGE($BL$31:$BL$34,2),$BL$31:$BL$34,0),10)} -> 0 | AN15: {=INDEX($AZ$31:$BL$34,MATCH(LARGE($BL$31:$BL$34,2),$BL$31:$BL$34,0),11)} -> 0 | AO15: {=INDEX($AZ$31:$BL$34,MATCH(LARGE($BL$31:$BL$34,2),$BL$31:$BL$34,0),12)} -> 0
A16: 3 | B16: {=INDEX($BA$21:$BA$24,MATCH(LARGE($BL$21:$BL$24,3),$BL$21:$BL$24,0))} -> 🇵🇾 | C16: {=INDEX($AZ$21:$AZ$24,MATCH(LARGE($BL$21:$BL$24,3),$BL$21:$BL$24,0))} -> Paraguay | D16: {=INDEX($AZ$21:$BL$24,MATCH(LARGE($BL$21:$BL$24,3),$BL$21:$BL$24,0),3)} -> 0 | E16: {=INDEX($AZ$21:$BL$24,MATCH(LARGE($BL$21:$BL$24,3),$BL$21:$BL$24,0),4)} -> 0 | F16: {=INDEX($AZ$21:$BL$24,MATCH(LARGE($BL$21:$BL$24,3),$BL$21:$BL$24,0),5)} -> 0 | G16: {=INDEX($AZ$21:$BL$24,MATCH(LARGE($BL$21:$BL$24,3),$BL$21:$BL$24,0),6)} -> 0 | H16: {=INDEX($AZ$21:$BL$24,MATCH(LARGE($BL$21:$BL$24,3),$BL$21:$BL$24,0),7)} -> 0 | I16: {=INDEX($AZ$21:$BL$24,MATCH(LARGE($BL$21:$BL$24,3),$BL$21:$BL$24,0),8)} -> 0 | J16: {=INDEX($AZ$21:$BL$24,MATCH(LARGE($BL$21:$BL$24,3),$BL$21:$BL$24,0),9)} -> 0 | K16: {=INDEX($AZ$21:$BL$24,MATCH(LARGE($BL$21:$BL$24,3),$BL$21:$BL$24,0),10)} -> 0 | L16: {=INDEX($AZ$21:$BL$24,MATCH(LARGE($BL$21:$BL$24,3),$BL$21:$BL$24,0),11)} -> 0 | M16: {=INDEX($AZ$21:$BL$24,MATCH(LARGE($BL$21:$BL$24,3),$BL$21:$BL$24,0),12)} -> 0 | O16: 3 | P16: {=INDEX($BA$26:$BA$29,MATCH(LARGE($BL$26:$BL$29,3),$BL$26:$BL$29,0))} -> 🇪🇨 | Q16: {=INDEX($AZ$26:$AZ$29,MATCH(LARGE($BL$26:$BL$29,3),$BL$26:$BL$29,0))} -> Ecuador | R16: {=INDEX($AZ$26:$BL$29,MATCH(LARGE($BL$26:$BL$29,3),$BL$26:$BL$29,0),3)} -> 0 | S16: {=INDEX($AZ$26:$BL$29,MATCH(LARGE($BL$26:$BL$29,3),$BL$26:$BL$29,0),4)} -> 0 | T16: {=INDEX($AZ$26:$BL$29,MATCH(LARGE($BL$26:$BL$29,3),$BL$26:$BL$29,0),5)} -> 0 | U16: {=INDEX($AZ$26:$BL$29,MATCH(LARGE($BL$26:$BL$29,3),$BL$26:$BL$29,0),6)} -> 0 | V16: {=INDEX($AZ$26:$BL$29,MATCH(LARGE($BL$26:$BL$29,3),$BL$26:$BL$29,0),7)} -> 0 | W16: {=INDEX($AZ$26:$BL$29,MATCH(LARGE($BL$26:$BL$29,3),$BL$26:$BL$29,0),8)} -> 0 | X16: {=INDEX($AZ$26:$BL$29,MATCH(LARGE($BL$26:$BL$29,3),$BL$26:$BL$29,0),9)} -> 0 | Y16: {=INDEX($AZ$26:$BL$29,MATCH(LARGE($BL$26:$BL$29,3),$BL$26:$BL$29,0),10)} -> 0 | Z16: {=INDEX($AZ$26:$BL$29,MATCH(LARGE($BL$26:$BL$29,3),$BL$26:$BL$29,0),11)} -> 0 | AA16: {=INDEX($AZ$26:$BL$29,MATCH(LARGE($BL$26:$BL$29,3),$BL$26:$BL$29,0),12)} -> 0 | AC16: 3 | AD16: {=INDEX($BA$31:$BA$34,MATCH(LARGE($BL$31:$BL$34,3),$BL$31:$BL$34,0))} -> 🇯🇵 | AE16: {=INDEX($AZ$31:$AZ$34,MATCH(LARGE($BL$31:$BL$34,3),$BL$31:$BL$34,0))} -> Japan | AF16: {=INDEX($AZ$31:$BL$34,MATCH(LARGE($BL$31:$BL$34,3),$BL$31:$BL$34,0),3)} -> 0 | AG16: {=INDEX($AZ$31:$BL$34,MATCH(LARGE($BL$31:$BL$34,3),$BL$31:$BL$34,0),4)} -> 0 | AH16: {=INDEX($AZ$31:$BL$34,MATCH(LARGE($BL$31:$BL$34,3),$BL$31:$BL$34,0),5)} -> 0 | AI16: {=INDEX($AZ$31:$BL$34,MATCH(LARGE($BL$31:$BL$34,3),$BL$31:$BL$34,0),6)} -> 0 | AJ16: {=INDEX($AZ$31:$BL$34,MATCH(LARGE($BL$31:$BL$34,3),$BL$31:$BL$34,0),7)} -> 0 | AK16: {=INDEX($AZ$31:$BL$34,MATCH(LARGE($BL$31:$BL$34,3),$BL$31:$BL$34,0),8)} -> 0 | AL16: {=INDEX($AZ$31:$BL$34,MATCH(LARGE($BL$31:$BL$34,3),$BL$31:$BL$34,0),9)} -> 0 | AM16: {=INDEX($AZ$31:$BL$34,MATCH(LARGE($BL$31:$BL$34,3),$BL$31:$BL$34,0),10)} -> 0 | AN16: {=INDEX($AZ$31:$BL$34,MATCH(LARGE($BL$31:$BL$34,3),$BL$31:$BL$34,0),11)} -> 0 | AO16: {=INDEX($AZ$31:$BL$34,MATCH(LARGE($BL$31:$BL$34,3),$BL$31:$BL$34,0),12)} -> 0 | AY16: C | AZ16: Brazil | BA16: 🇧🇷 | BB16: =SUMPRODUCT(('DU DOAN'!$B$4:$B$107="Vòng bảng")*('DU DOAN'!$D$4:$D$107="C")*ISNUMBER('DU DOAN'!$K$4:$K$107)*ISNUMBER('DU DOAN'!$L$4:$L$107)*(('DU DOAN'!$H$4:$H$107="Brazil")+('DU DOAN'!$I$4:$I$107="Brazil"))) -> 0 | BC16: =SUMPRODUCT(('DU DOAN'!$B$4:$B$107="Vòng bảng")*('DU DOAN'!$D$4:$D$107="C")*ISNUMBER('DU DOAN'!$K$4:$K$107)*ISNUMBER('DU DOAN'!$L$4:$L$107)*(('DU DOAN'!$H$4:$H$107="Brazil")*('DU DOAN'!$K$4:$K$107>'DU DOAN'!$L$4:$L$107)+('DU DOAN'!$I$4:$I$107="Brazil")*('DU DOAN'!$L$4:$L$107>'DU DOAN'!$K$4:$K$107))) -> 0 | BD16: =SUMPRODUCT(('DU DOAN'!$B$4:$B$107="Vòng bảng")*('DU DOAN'!$D$4:$D$107="C")*ISNUMBER('DU DOAN'!$K$4:$K$107)*ISNUMBER('DU DOAN'!$L$4:$L$107)*(('DU DOAN'!$H$4:$H$107="Brazil")*('DU DOAN'!$K$4:$K$107='DU DOAN'!$L$4:$L$107)+('DU DOAN'!$I$4:$I$107="Brazil")*('DU DOAN'!$K$4:$K$107='DU DOAN'!$L$4:$L$107))) -> 0 | BE16: =SUMPRODUCT(('DU DOAN'!$B$4:$B$107="Vòng bảng")*('DU DOAN'!$D$4:$D$107="C")*ISNUMBER('DU DOAN'!$K$4:$K$107)*ISNUMBER('DU DOAN'!$L$4:$L$107)*(('DU DOAN'!$H$4:$H$107="Brazil")*('DU DOAN'!$K$4:$K$107<'DU DOAN'!$L$4:$L$107)+('DU DOAN'!$I$4:$I$107="Brazil")*('DU DOAN'!$L$4:$L$107<'DU DOAN'!$K$4:$K$107))) -> 0 | BF16: =SUMPRODUCT(('DU DOAN'!$B$4:$B$107="Vòng bảng")*('DU DOAN'!$D$4:$D$107="C")*ISNUMBER('DU DOAN'!$K$4:$K$107)*ISNUMBER('DU DOAN'!$L$4:$L$107)*(('DU DOAN'!$H$4:$H$107="Brazil")*'DU DOAN'!$K$4:$K$107+('DU DOAN'!$I$4:$I$107="Brazil")*'DU DOAN'!$L$4:$L$107)) -> 0 | BG16: =SUMPRODUCT(('DU DOAN'!$B$4:$B$107="Vòng bảng")*('DU DOAN'!$D$4:$D$107="C")*ISNUMBER('DU DOAN'!$K$4:$K$107)*ISNUMBER('DU DOAN'!$L$4:$L$107)*(('DU DOAN'!$H$4:$H$107="Brazil")*'DU DOAN'!$L$4:$L$107+('DU DOAN'!$I$4:$I$107="Brazil")*'DU DOAN'!$K$4:$K$107)) -> 0 | BH16: =BF16-BG16 -> 0 | BI16: =SUMPRODUCT(IFERROR((#REF!="Brazil")*#REF!,0))+SUMPRODUCT(IFERROR((#REF!="Brazil")*#REF!,0)) -> 0 | BJ16: =SUMPRODUCT(IFERROR((#REF!="Brazil")*#REF!,0))+SUMPRODUCT(IFERROR((#REF!="Brazil")*#REF!,0)) -> 0 | BK16: =3*BC16+BD16 -> 0 | BL16: =BK16*1000000+BH16*10000+BF16*100+4 -> 4
A17: 4 | B17: {=INDEX($BA$21:$BA$24,MATCH(LARGE($BL$21:$BL$24,4),$BL$21:$BL$24,0))} -> 🇦🇺 | C17: {=INDEX($AZ$21:$AZ$24,MATCH(LARGE($BL$21:$BL$24,4),$BL$21:$BL$24,0))} -> Australia | D17: {=INDEX($AZ$21:$BL$24,MATCH(LARGE($BL$21:$BL$24,4),$BL$21:$BL$24,0),3)} -> 0 | E17: {=INDEX($AZ$21:$BL$24,MATCH(LARGE($BL$21:$BL$24,4),$BL$21:$BL$24,0),4)} -> 0 | F17: {=INDEX($AZ$21:$BL$24,MATCH(LARGE($BL$21:$BL$24,4),$BL$21:$BL$24,0),5)} -> 0 | G17: {=INDEX($AZ$21:$BL$24,MATCH(LARGE($BL$21:$BL$24,4),$BL$21:$BL$24,0),6)} -> 0 | H17: {=INDEX($AZ$21:$BL$24,MATCH(LARGE($BL$21:$BL$24,4),$BL$21:$BL$24,0),7)} -> 0 | I17: {=INDEX($AZ$21:$BL$24,MATCH(LARGE($BL$21:$BL$24,4),$BL$21:$BL$24,0),8)} -> 0 | J17: {=INDEX($AZ$21:$BL$24,MATCH(LARGE($BL$21:$BL$24,4),$BL$21:$BL$24,0),9)} -> 0 | K17: {=INDEX($AZ$21:$BL$24,MATCH(LARGE($BL$21:$BL$24,4),$BL$21:$BL$24,0),10)} -> 0 | L17: {=INDEX($AZ$21:$BL$24,MATCH(LARGE($BL$21:$BL$24,4),$BL$21:$BL$24,0),11)} -> 0 | M17: {=INDEX($AZ$21:$BL$24,MATCH(LARGE($BL$21:$BL$24,4),$BL$21:$BL$24,0),12)} -> 0 | O17: 4 | P17: {=INDEX($BA$26:$BA$29,MATCH(LARGE($BL$26:$BL$29,4),$BL$26:$BL$29,0))} -> 🇨🇼 | Q17: {=INDEX($AZ$26:$AZ$29,MATCH(LARGE($BL$26:$BL$29,4),$BL$26:$BL$29,0))} -> Curaçao | R17: {=INDEX($AZ$26:$BL$29,MATCH(LARGE($BL$26:$BL$29,4),$BL$26:$BL$29,0),3)} -> 0 | S17: {=INDEX($AZ$26:$BL$29,MATCH(LARGE($BL$26:$BL$29,4),$BL$26:$BL$29,0),4)} -> 0 | T17: {=INDEX($AZ$26:$BL$29,MATCH(LARGE($BL$26:$BL$29,4),$BL$26:$BL$29,0),5)} -> 0 | U17: {=INDEX($AZ$26:$BL$29,MATCH(LARGE($BL$26:$BL$29,4),$BL$26:$BL$29,0),6)} -> 0 | V17: {=INDEX($AZ$26:$BL$29,MATCH(LARGE($BL$26:$BL$29,4),$BL$26:$BL$29,0),7)} -> 0 | W17: {=INDEX($AZ$26:$BL$29,MATCH(LARGE($BL$26:$BL$29,4),$BL$26:$BL$29,0),8)} -> 0 | X17: {=INDEX($AZ$26:$BL$29,MATCH(LARGE($BL$26:$BL$29,4),$BL$26:$BL$29,0),9)} -> 0 | Y17: {=INDEX($AZ$26:$BL$29,MATCH(LARGE($BL$26:$BL$29,4),$BL$26:$BL$29,0),10)} -> 0 | Z17: {=INDEX($AZ$26:$BL$29,MATCH(LARGE($BL$26:$BL$29,4),$BL$26:$BL$29,0),11)} -> 0 | AA17: {=INDEX($AZ$26:$BL$29,MATCH(LARGE($BL$26:$BL$29,4),$BL$26:$BL$29,0),12)} -> 0 | AC17: 4 | AD17: {=INDEX($BA$31:$BA$34,MATCH(LARGE($BL$31:$BL$34,4),$BL$31:$BL$34,0))} -> 🇹🇳 | AE17: {=INDEX($AZ$31:$AZ$34,MATCH(LARGE($BL$31:$BL$34,4),$BL$31:$BL$34,0))} -> Tunisia | AF17: {=INDEX($AZ$31:$BL$34,MATCH(LARGE($BL$31:$BL$34,4),$BL$31:$BL$34,0),3)} -> 0 | AG17: {=INDEX($AZ$31:$BL$34,MATCH(LARGE($BL$31:$BL$34,4),$BL$31:$BL$34,0),4)} -> 0 | AH17: {=INDEX($AZ$31:$BL$34,MATCH(LARGE($BL$31:$BL$34,4),$BL$31:$BL$34,0),5)} -> 0 | AI17: {=INDEX($AZ$31:$BL$34,MATCH(LARGE($BL$31:$BL$34,4),$BL$31:$BL$34,0),6)} -> 0 | AJ17: {=INDEX($AZ$31:$BL$34,MATCH(LARGE($BL$31:$BL$34,4),$BL$31:$BL$34,0),7)} -> 0 | AK17: {=INDEX($AZ$31:$BL$34,MATCH(LARGE($BL$31:$BL$34,4),$BL$31:$BL$34,0),8)} -> 0 | AL17: {=INDEX($AZ$31:$BL$34,MATCH(LARGE($BL$31:$BL$34,4),$BL$31:$BL$34,0),9)} -> 0 | AM17: {=INDEX($AZ$31:$BL$34,MATCH(LARGE($BL$31:$BL$34,4),$BL$31:$BL$34,0),10)} -> 0 | AN17: {=INDEX($AZ$31:$BL$34,MATCH(LARGE($BL$31:$BL$34,4),$BL$31:$BL$34,0),11)} -> 0 | AO17: {=INDEX($AZ$31:$BL$34,MATCH(LARGE($BL$31:$BL$34,4),$BL$31:$BL$34,0),12)} -> 0 | AZ17: Scotland | BA17: 🏴󠁧󠁢󠁳󠁣󠁴󠁿 | BB17: =SUMPRODUCT(('DU DOAN'!$B$4:$B$107="Vòng bảng")*('DU DOAN'!$D$4:$D$107="C")*ISNUMBER('DU DOAN'!$K$4:$K$107)*ISNUMBER('DU DOAN'!$L$4:$L$107)*(('DU DOAN'!$H$4:$H$107="Scotland")+('DU DOAN'!$I$4:$I$107="Scotland"))) -> 0 | BC17: =SUMPRODUCT(('DU DOAN'!$B$4:$B$107="Vòng bảng")*('DU DOAN'!$D$4:$D$107="C")*ISNUMBER('DU DOAN'!$K$4:$K$107)*ISNUMBER('DU DOAN'!$L$4:$L$107)*(('DU DOAN'!$H$4:$H$107="Scotland")*('DU DOAN'!$K$4:$K$107>'DU DOAN'!$L$4:$L$107)+('DU DOAN'!$I$4:$I$107="Scotland")*('DU DOAN'!$L$4:$L$107>'DU DOAN'!$K$4:$K$107))) -> 0 | BD17: =SUMPRODUCT(('DU DOAN'!$B$4:$B$107="Vòng bảng")*('DU DOAN'!$D$4:$D$107="C")*ISNUMBER('DU DOAN'!$K$4:$K$107)*ISNUMBER('DU DOAN'!$L$4:$L$107)*(('DU DOAN'!$H$4:$H$107="Scotland")*('DU DOAN'!$K$4:$K$107='DU DOAN'!$L$4:$L$107)+('DU DOAN'!$I$4:$I$107="Scotland")*('DU DOAN'!$K$4:$K$107='DU DOAN'!$L$4:$L$107))) -> 0 | BE17: =SUMPRODUCT(('DU DOAN'!$B$4:$B$107="Vòng bảng")*('DU DOAN'!$D$4:$D$107="C")*ISNUMBER('DU DOAN'!$K$4:$K$107)*ISNUMBER('DU DOAN'!$L$4:$L$107)*(('DU DOAN'!$H$4:$H$107="Scotland")*('DU DOAN'!$K$4:$K$107<'DU DOAN'!$L$4:$L$107)+('DU DOAN'!$I$4:$I$107="Scotland")*('DU DOAN'!$L$4:$L$107<'DU DOAN'!$K$4:$K$107))) -> 0 | BF17: =SUMPRODUCT(('DU DOAN'!$B$4:$B$107="Vòng bảng")*('DU DOAN'!$D$4:$D$107="C")*ISNUMBER('DU DOAN'!$K$4:$K$107)*ISNUMBER('DU DOAN'!$L$4:$L$107)*(('DU DOAN'!$H$4:$H$107="Scotland")*'DU DOAN'!$K$4:$K$107+('DU DOAN'!$I$4:$I$107="Scotland")*'DU DOAN'!$L$4:$L$107)) -> 0 | BG17: =SUMPRODUCT(('DU DOAN'!$B$4:$B$107="Vòng bảng")*('DU DOAN'!$D$4:$D$107="C")*ISNUMBER('DU DOAN'!$K$4:$K$107)*ISNUMBER('DU DOAN'!$L$4:$L$107)*(('DU DOAN'!$H$4:$H$107="Scotland")*'DU DOAN'!$L$4:$L$107+('DU DOAN'!$I$4:$I$107="Scotland")*'DU DOAN'!$K$4:$K$107)) -> 0 | BH17: =BF17-BG17 -> 0 | BI17: =SUMPRODUCT(IFERROR((#REF!="Scotland")*#REF!,0))+SUMPRODUCT(IFERROR((#REF!="Scotland")*#REF!,0)) -> 0 | BJ17: =SUMPRODUCT(IFERROR((#REF!="Scotland")*#REF!,0))+SUMPRODUCT(IFERROR((#REF!="Scotland")*#REF!,0)) -> 0 | BK17: =3*BC17+BD17 -> 0 | BL17: =BK17*1000000+BH17*10000+BF17*100+3 -> 3
AZ18: Morocco | BA18: 🇲🇦 | BB18: =SUMPRODUCT(('DU DOAN'!$B$4:$B$107="Vòng bảng")*('DU DOAN'!$D$4:$D$107="C")*ISNUMBER('DU DOAN'!$K$4:$K$107)*ISNUMBER('DU DOAN'!$L$4:$L$107)*(('DU DOAN'!$H$4:$H$107="Morocco")+('DU DOAN'!$I$4:$I$107="Morocco"))) -> 0 | BC18: =SUMPRODUCT(('DU DOAN'!$B$4:$B$107="Vòng bảng")*('DU DOAN'!$D$4:$D$107="C")*ISNUMBER('DU DOAN'!$K$4:$K$107)*ISNUMBER('DU DOAN'!$L$4:$L$107)*(('DU DOAN'!$H$4:$H$107="Morocco")*('DU DOAN'!$K$4:$K$107>'DU DOAN'!$L$4:$L$107)+('DU DOAN'!$I$4:$I$107="Morocco")*('DU DOAN'!$L$4:$L$107>'DU DOAN'!$K$4:$K$107))) -> 0 | BD18: =SUMPRODUCT(('DU DOAN'!$B$4:$B$107="Vòng bảng")*('DU DOAN'!$D$4:$D$107="C")*ISNUMBER('DU DOAN'!$K$4:$K$107)*ISNUMBER('DU DOAN'!$L$4:$L$107)*(('DU DOAN'!$H$4:$H$107="Morocco")*('DU DOAN'!$K$4:$K$107='DU DOAN'!$L$4:$L$107)+('DU DOAN'!$I$4:$I$107="Morocco")*('DU DOAN'!$K$4:$K$107='DU DOAN'!$L$4:$L$107))) -> 0 | BE18: =SUMPRODUCT(('DU DOAN'!$B$4:$B$107="Vòng bảng")*('DU DOAN'!$D$4:$D$107="C")*ISNUMBER('DU DOAN'!$K$4:$K$107)*ISNUMBER('DU DOAN'!$L$4:$L$107)*(('DU DOAN'!$H$4:$H$107="Morocco")*('DU DOAN'!$K$4:$K$107<'DU DOAN'!$L$4:$L$107)+('DU DOAN'!$I$4:$I$107="Morocco")*('DU DOAN'!$L$4:$L$107<'DU DOAN'!$K$4:$K$107))) -> 0 | BF18: =SUMPRODUCT(('DU DOAN'!$B$4:$B$107="Vòng bảng")*('DU DOAN'!$D$4:$D$107="C")*ISNUMBER('DU DOAN'!$K$4:$K$107)*ISNUMBER('DU DOAN'!$L$4:$L$107)*(('DU DOAN'!$H$4:$H$107="Morocco")*'DU DOAN'!$K$4:$K$107+('DU DOAN'!$I$4:$I$107="Morocco")*'DU DOAN'!$L$4:$L$107)) -> 0 | BG18: =SUMPRODUCT(('DU DOAN'!$B$4:$B$107="Vòng bảng")*('DU DOAN'!$D$4:$D$107="C")*ISNUMBER('DU DOAN'!$K$4:$K$107)*ISNUMBER('DU DOAN'!$L$4:$L$107)*(('DU DOAN'!$H$4:$H$107="Morocco")*'DU DOAN'!$L$4:$L$107+('DU DOAN'!$I$4:$I$107="Morocco")*'DU DOAN'!$K$4:$K$107)) -> 0 | BH18: =BF18-BG18 -> 0 | BI18: =SUMPRODUCT(IFERROR((#REF!="Morocco")*#REF!,0))+SUMPRODUCT(IFERROR((#REF!="Morocco")*#REF!,0)) -> 0 | BJ18: =SUMPRODUCT(IFERROR((#REF!="Morocco")*#REF!,0))+SUMPRODUCT(IFERROR((#REF!="Morocco")*#REF!,0)) -> 0 | BK18: =3*BC18+BD18 -> 0 | BL18: =BK18*1000000+BH18*10000+BF18*100+2 -> 2
A19: BẢNG G | O19: BẢNG H | AC19: BẢNG I | AZ19: Haiti | BA19: 🇭🇹 | BB19: =SUMPRODUCT(('DU DOAN'!$B$4:$B$107="Vòng bảng")*('DU DOAN'!$D$4:$D$107="C")*ISNUMBER('DU DOAN'!$K$4:$K$107)*ISNUMBER('DU DOAN'!$L$4:$L$107)*(('DU DOAN'!$H$4:$H$107="Haiti")+('DU DOAN'!$I$4:$I$107="Haiti"))) -> 0 | BC19: =SUMPRODUCT(('DU DOAN'!$B$4:$B$107="Vòng bảng")*('DU DOAN'!$D$4:$D$107="C")*ISNUMBER('DU DOAN'!$K$4:$K$107)*ISNUMBER('DU DOAN'!$L$4:$L$107)*(('DU DOAN'!$H$4:$H$107="Haiti")*('DU DOAN'!$K$4:$K$107>'DU DOAN'!$L$4:$L$107)+('DU DOAN'!$I$4:$I$107="Haiti")*('DU DOAN'!$L$4:$L$107>'DU DOAN'!$K$4:$K$107))) -> 0 | BD19: =SUMPRODUCT(('DU DOAN'!$B$4:$B$107="Vòng bảng")*('DU DOAN'!$D$4:$D$107="C")*ISNUMBER('DU DOAN'!$K$4:$K$107)*ISNUMBER('DU DOAN'!$L$4:$L$107)*(('DU DOAN'!$H$4:$H$107="Haiti")*('DU DOAN'!$K$4:$K$107='DU DOAN'!$L$4:$L$107)+('DU DOAN'!$I$4:$I$107="Haiti")*('DU DOAN'!$K$4:$K$107='DU DOAN'!$L$4:$L$107))) -> 0 | BE19: =SUMPRODUCT(('DU DOAN'!$B$4:$B$107="Vòng bảng")*('DU DOAN'!$D$4:$D$107="C")*ISNUMBER('DU DOAN'!$K$4:$K$107)*ISNUMBER('DU DOAN'!$L$4:$L$107)*(('DU DOAN'!$H$4:$H$107="Haiti")*('DU DOAN'!$K$4:$K$107<'DU DOAN'!$L$4:$L$107)+('DU DOAN'!$I$4:$I$107="Haiti")*('DU DOAN'!$L$4:$L$107<'DU DOAN'!$K$4:$K$107))) -> 0 | BF19: =SUMPRODUCT(('DU DOAN'!$B$4:$B$107="Vòng bảng")*('DU DOAN'!$D$4:$D$107="C")*ISNUMBER('DU DOAN'!$K$4:$K$107)*ISNUMBER('DU DOAN'!$L$4:$L$107)*(('DU DOAN'!$H$4:$H$107="Haiti")*'DU DOAN'!$K$4:$K$107+('DU DOAN'!$I$4:$I$107="Haiti")*'DU DOAN'!$L$4:$L$107)) -> 0 | BG19: =SUMPRODUCT(('DU DOAN'!$B$4:$B$107="Vòng bảng")*('DU DOAN'!$D$4:$D$107="C")*ISNUMBER('DU DOAN'!$K$4:$K$107)*ISNUMBER('DU DOAN'!$L$4:$L$107)*(('DU DOAN'!$H$4:$H$107="Haiti")*'DU DOAN'!$L$4:$L$107+('DU DOAN'!$I$4:$I$107="Haiti")*'DU DOAN'!$K$4:$K$107)) -> 0 | BH19: =BF19-BG19 -> 0 | BI19: =SUMPRODUCT(IFERROR((#REF!="Haiti")*#REF!,0))+SUMPRODUCT(IFERROR((#REF!="Haiti")*#REF!,0)) -> 0 | BJ19: =SUMPRODUCT(IFERROR((#REF!="Haiti")*#REF!,0))+SUMPRODUCT(IFERROR((#REF!="Haiti")*#REF!,0)) -> 0 | BK19: =3*BC19+BD19 -> 0 | BL19: =BK19*1000000+BH19*10000+BF19*100+1 -> 1
A20: # | B20: 🏴 | C20: Đội tuyển | D20: Đá | E20: T | F20: H | G20: B | H20: GF | I20: GA | J20: GD | K20: 🟨 | L20: 🟥 | M20: Pts | O20: # | P20: 🏴 | Q20: Đội tuyển | R20: Đá | S20: T | T20: H | U20: B | V20: GF | W20: GA | X20: GD | Y20: 🟨 | Z20: 🟥 | AA20: Pts | AC20: # | AD20: 🏴 | AE20: Đội tuyển | AF20: Đá | AG20: T | AH20: H | AI20: B | AJ20: GF | AK20: GA | AL20: GD | AM20: 🟨 | AN20: 🟥 | AO20: Pts
A21: 1 | B21: {=INDEX($BA$36:$BA$39,MATCH(LARGE($BL$36:$BL$39,1),$BL$36:$BL$39,0))} -> 🇧🇪 | C21: {=INDEX($AZ$36:$AZ$39,MATCH(LARGE($BL$36:$BL$39,1),$BL$36:$BL$39,0))} -> Belgium | D21: {=INDEX($AZ$36:$BL$39,MATCH(LARGE($BL$36:$BL$39,1),$BL$36:$BL$39,0),3)} -> 0 | E21: {=INDEX($AZ$36:$BL$39,MATCH(LARGE($BL$36:$BL$39,1),$BL$36:$BL$39,0),4)} -> 0 | F21: {=INDEX($AZ$36:$BL$39,MATCH(LARGE($BL$36:$BL$39,1),$BL$36:$BL$39,0),5)} -> 0 | G21: {=INDEX($AZ$36:$BL$39,MATCH(LARGE($BL$36:$BL$39,1),$BL$36:$BL$39,0),6)} -> 0 | H21: {=INDEX($AZ$36:$BL$39,MATCH(LARGE($BL$36:$BL$39,1),$BL$36:$BL$39,0),7)} -> 0 | I21: {=INDEX($AZ$36:$BL$39,MATCH(LARGE($BL$36:$BL$39,1),$BL$36:$BL$39,0),8)} -> 0 | J21: {=INDEX($AZ$36:$BL$39,MATCH(LARGE($BL$36:$BL$39,1),$BL$36:$BL$39,0),9)} -> 0 | K21: {=INDEX($AZ$36:$BL$39,MATCH(LARGE($BL$36:$BL$39,1),$BL$36:$BL$39,0),10)} -> 0 | L21: {=INDEX($AZ$36:$BL$39,MATCH(LARGE($BL$36:$BL$39,1),$BL$36:$BL$39,0),11)} -> 0 | M21: {=INDEX($AZ$36:$BL$39,MATCH(LARGE($BL$36:$BL$39,1),$BL$36:$BL$39,0),12)} -> 0 | O21: 1 | P21: {=INDEX($BA$41:$BA$44,MATCH(LARGE($BL$41:$BL$44,1),$BL$41:$BL$44,0))} -> 🇪🇸 | Q21: {=INDEX($AZ$41:$AZ$44,MATCH(LARGE($BL$41:$BL$44,1),$BL$41:$BL$44,0))} -> Spain | R21: {=INDEX($AZ$41:$BL$44,MATCH(LARGE($BL$41:$BL$44,1),$BL$41:$BL$44,0),3)} -> 0 | S21: {=INDEX($AZ$41:$BL$44,MATCH(LARGE($BL$41:$BL$44,1),$BL$41:$BL$44,0),4)} -> 0 | T21: {=INDEX($AZ$41:$BL$44,MATCH(LARGE($BL$41:$BL$44,1),$BL$41:$BL$44,0),5)} -> 0 | U21: {=INDEX($AZ$41:$BL$44,MATCH(LARGE($BL$41:$BL$44,1),$BL$41:$BL$44,0),6)} -> 0 | V21: {=INDEX($AZ$41:$BL$44,MATCH(LARGE($BL$41:$BL$44,1),$BL$41:$BL$44,0),7)} -> 0 | W21: {=INDEX($AZ$41:$BL$44,MATCH(LARGE($BL$41:$BL$44,1),$BL$41:$BL$44,0),8)} -> 0 | X21: {=INDEX($AZ$41:$BL$44,MATCH(LARGE($BL$41:$BL$44,1),$BL$41:$BL$44,0),9)} -> 0 | Y21: {=INDEX($AZ$41:$BL$44,MATCH(LARGE($BL$41:$BL$44,1),$BL$41:$BL$44,0),10)} -> 0 | Z21: {=INDEX($AZ$41:$BL$44,MATCH(LARGE($BL$41:$BL$44,1),$BL$41:$BL$44,0),11)} -> 0 | AA21: {=INDEX($AZ$41:$BL$44,MATCH(LARGE($BL$41:$BL$44,1),$BL$41:$BL$44,0),12)} -> 0 | AC21: 1 | AD21: {=INDEX($BA$46:$BA$49,MATCH(LARGE($BL$46:$BL$49,1),$BL$46:$BL$49,0))} -> 🇫🇷 | AE21: {=INDEX($AZ$46:$AZ$49,MATCH(LARGE($BL$46:$BL$49,1),$BL$46:$BL$49,0))} -> France | AF21: {=INDEX($AZ$46:$BL$49,MATCH(LARGE($BL$46:$BL$49,1),$BL$46:$BL$49,0),3)} -> 0 | AG21: {=INDEX($AZ$46:$BL$49,MATCH(LARGE($BL$46:$BL$49,1),$BL$46:$BL$49,0),4)} -> 0 | AH21: {=INDEX($AZ$46:$BL$49,MATCH(LARGE($BL$46:$BL$49,1),$BL$46:$BL$49,0),5)} -> 0 | AI21: {=INDEX($AZ$46:$BL$49,MATCH(LARGE($BL$46:$BL$49,1),$BL$46:$BL$49,0),6)} -> 0 | AJ21: {=INDEX($AZ$46:$BL$49,MATCH(LARGE($BL$46:$BL$49,1),$BL$46:$BL$49,0),7)} -> 0 | AK21: {=INDEX($AZ$46:$BL$49,MATCH(LARGE($BL$46:$BL$49,1),$BL$46:$BL$49,0),8)} -> 0 | AL21: {=INDEX($AZ$46:$BL$49,MATCH(LARGE($BL$46:$BL$49,1),$BL$46:$BL$49,0),9)} -> 0 | AM21: {=INDEX($AZ$46:$BL$49,MATCH(LARGE($BL$46:$BL$49,1),$BL$46:$BL$49,0),10)} -> 0 | AN21: {=INDEX($AZ$46:$BL$49,MATCH(LARGE($BL$46:$BL$49,1),$BL$46:$BL$49,0),11)} -> 0 | AO21: {=INDEX($AZ$46:$BL$49,MATCH(LARGE($BL$46:$BL$49,1),$BL$46:$BL$49,0),12)} -> 0 | AY21: D | AZ21: United States | BA21: 🇺🇸 | BB21: =SUMPRODUCT(('DU DOAN'!$B$4:$B$107="Vòng bảng")*('DU DOAN'!$D$4:$D$107="D")*ISNUMBER('DU DOAN'!$K$4:$K$107)*ISNUMBER('DU DOAN'!$L$4:$L$107)*(('DU DOAN'!$H$4:$H$107="United States")+('DU DOAN'!$I$4:$I$107="United States"))) -> 0 | BC21: =SUMPRODUCT(('DU DOAN'!$B$4:$B$107="Vòng bảng")*('DU DOAN'!$D$4:$D$107="D")*ISNUMBER('DU DOAN'!$K$4:$K$107)*ISNUMBER('DU DOAN'!$L$4:$L$107)*(('DU DOAN'!$H$4:$H$107="United States")*('DU DOAN'!$K$4:$K$107>'DU DOAN'!$L$4:$L$107)+('DU DOAN'!$I$4:$I$107="United States")*('DU DOAN'!$L$4:$L$107>'DU DOAN'!$K$4:$K$107))) -> 0 | BD21: =SUMPRODUCT(('DU DOAN'!$B$4:$B$107="Vòng bảng")*('DU DOAN'!$D$4:$D$107="D")*ISNUMBER('DU DOAN'!$K$4:$K$107)*ISNUMBER('DU DOAN'!$L$4:$L$107)*(('DU DOAN'!$H$4:$H$107="United States")*('DU DOAN'!$K$4:$K$107='DU DOAN'!$L$4:$L$107)+('DU DOAN'!$I$4:$I$107="United States")*('DU DOAN'!$K$4:$K$107='DU DOAN'!$L$4:$L$107))) -> 0 | BE21: =SUMPRODUCT(('DU DOAN'!$B$4:$B$107="Vòng bảng")*('DU DOAN'!$D$4:$D$107="D")*ISNUMBER('DU DOAN'!$K$4:$K$107)*ISNUMBER('DU DOAN'!$L$4:$L$107)*(('DU DOAN'!$H$4:$H$107="United States")*('DU DOAN'!$K$4:$K$107<'DU DOAN'!$L$4:$L$107)+('DU DOAN'!$I$4:$I$107="United States")*('DU DOAN'!$L$4:$L$107<'DU DOAN'!$K$4:$K$107))) -> 0 | BF21: =SUMPRODUCT(('DU DOAN'!$B$4:$B$107="Vòng bảng")*('DU DOAN'!$D$4:$D$107="D")*ISNUMBER('DU DOAN'!$K$4:$K$107)*ISNUMBER('DU DOAN'!$L$4:$L$107)*(('DU DOAN'!$H$4:$H$107="United States")*'DU DOAN'!$K$4:$K$107+('DU DOAN'!$I$4:$I$107="United States")*'DU DOAN'!$L$4:$L$107)) -> 0 | BG21: =SUMPRODUCT(('DU DOAN'!$B$4:$B$107="Vòng bảng")*('DU DOAN'!$D$4:$D$107="D")*ISNUMBER('DU DOAN'!$K$4:$K$107)*ISNUMBER('DU DOAN'!$L$4:$L$107)*(('DU DOAN'!$H$4:$H$107="United States")*'DU DOAN'!$L$4:$L$107+('DU DOAN'!$I$4:$I$107="United States")*'DU DOAN'!$K$4:$K$107)) -> 0 | BH21: =BF21-BG21 -> 0 | BI21: =SUMPRODUCT(IFERROR((#REF!="United States")*#REF!,0))+SUMPRODUCT(IFERROR((#REF!="United States")*#REF!,0)) -> 0 | BJ21: =SUMPRODUCT(IFERROR((#REF!="United States")*#REF!,0))+SUMPRODUCT(IFERROR((#REF!="United States")*#REF!,0)) -> 0 | BK21: =3*BC21+BD21 -> 0 | BL21: =BK21*1000000+BH21*10000+BF21*100+4 -> 4
